STARTED:[2015-02-18|04:25:25]
[EXCEPTION] [2015-02-18|04:25:25] An Exception occurred!
''
[EXCEPTION] [2015-02-18|04:25:25] Traceback (most recent call last):
  File "C:\Users\PD\Documents\polly\pythonDongle\remote_monitor.py", line 15, in send_request
    wp = urllib2.urlopen(http_request, timeout=d.web_request_timeout)
  File "C:\Python34\lib\urllib\request.py", line 153, in urlopen
    return opener.open(url, data, timeout)
  File "C:\Python34\lib\urllib\request.py", line 455, in open
    response = self._open(req, data)
  File "C:\Python34\lib\urllib\request.py", line 473, in _open
    '_open', req)
  File "C:\Python34\lib\urllib\request.py", line 433, in _call_chain
    result = func(*args)
  File "C:\Python34\lib\urllib\request.py", line 1215, in http_open
    return self.do_open(http.client.HTTPConnection, req)
  File "C:\Python34\lib\urllib\request.py", line 1194, in do_open
    r = h.getresponse()
  File "C:\Python34\lib\http\client.py", line 1172, in getresponse
    response.begin()
  File "C:\Python34\lib\http\client.py", line 351, in begin
    version, status, reason = self._read_status()
  File "C:\Python34\lib\http\client.py", line 321, in _read_status
    raise BadStatusLine(line)
http.client.BadStatusLine: ''
[EXCEPTION] [2015-02-18|04:25:25] Moving on... Tired of getting SMSs about this...
[EXCEPTION] [2015-02-18|04:29:47] >>>> Retrying request: http://128.2.211.183/wa/RemoteMonitor/dongleMontiorUpdate.php?update=QUxJVkU7WzIwMTUtMDItMTh8MDQ6MjU6MjRdOzE7MTY7Q2VsbGNvbSBHTjtSRUFEWTtDT00yMg==
[EXCEPTION] [2015-02-18|07:30:14] An Exception occurred!
''
[EXCEPTION] [2015-02-18|07:30:14] Traceback (most recent call last):
  File "C:\Users\PD\Documents\polly\pythonDongle\remote_monitor.py", line 15, in send_request
    wp = urllib2.urlopen(http_request, timeout=d.web_request_timeout)
  File "C:\Python34\lib\urllib\request.py", line 153, in urlopen
    return opener.open(url, data, timeout)
  File "C:\Python34\lib\urllib\request.py", line 455, in open
    response = self._open(req, data)
  File "C:\Python34\lib\urllib\request.py", line 473, in _open
    '_open', req)
  File "C:\Python34\lib\urllib\request.py", line 433, in _call_chain
    result = func(*args)
  File "C:\Python34\lib\urllib\request.py", line 1215, in http_open
    return self.do_open(http.client.HTTPConnection, req)
  File "C:\Python34\lib\urllib\request.py", line 1194, in do_open
    r = h.getresponse()
  File "C:\Python34\lib\http\client.py", line 1172, in getresponse
    response.begin()
  File "C:\Python34\lib\http\client.py", line 351, in begin
    version, status, reason = self._read_status()
  File "C:\Python34\lib\http\client.py", line 321, in _read_status
    raise BadStatusLine(line)
http.client.BadStatusLine: ''
[EXCEPTION] [2015-02-18|07:30:14] Moving on... Tired of getting SMSs about this...
[EXCEPTION] [2015-02-18|07:34:47] >>>> Retrying request: http://128.2.211.183/wa/RemoteMonitor/dongleMontiorUpdate.php?update=TE9HO1tDT00yMl0gWzIwMTUtMDItMTh8MDc6MzA6MDldIFdhaXRpbmcgZm9yIGEgY2FsbCBmcm9tIEdvZG90Li4uIE5vdGhpbmcgdG8gYmUgZG9uZS4uLgo=
[EXCEPTION] [2015-02-18|10:40:16] URL Error... Timeout?
HTTP Error 404: Not Found
[EXCEPTION] [2015-02-18|10:40:16] URL Error... Timeout?
HTTP Error 404: Not Found
[EXCEPTION] [2015-02-18|10:40:16] Traceback (most recent call last):
  File "C:\Users\PD\Documents\polly\pythonDongle\remote_monitor.py", line 15, in send_request
    wp = urllib2.urlopen(http_request, timeout=d.web_request_timeout)
  File "C:\Python34\lib\urllib\request.py", line 153, in urlopen
    return opener.open(url, data, timeout)
  File "C:\Python34\lib\urllib\request.py", line 461, in open
    response = meth(req, response)
  File "C:\Python34\lib\urllib\request.py", line 571, in http_response
    'http', request, response, code, msg, hdrs)
  File "C:\Python34\lib\urllib\request.py", line 499, in error
    return self._call_chain(*args)
  File "C:\Python34\lib\urllib\request.py", line 433, in _call_chain
    result = func(*args)
  File "C:\Python34\lib\urllib\request.py", line 579, in http_error_default
    raise HTTPError(req.full_url, code, msg, hdrs, fp)
urllib.error.HTTPError: HTTP Error 404: Not Found
[EXCEPTION] [2015-02-18|10:40:16] Traceback (most recent call last):
  File "C:\Users\PD\Documents\polly\pythonDongle\remote_monitor.py", line 15, in send_request
    wp = urllib2.urlopen(http_request, timeout=d.web_request_timeout)
  File "C:\Python34\lib\urllib\request.py", line 153, in urlopen
    return opener.open(url, data, timeout)
  File "C:\Python34\lib\urllib\request.py", line 461, in open
    response = meth(req, response)
  File "C:\Python34\lib\urllib\request.py", line 571, in http_response
    'http', request, response, code, msg, hdrs)
  File "C:\Python34\lib\urllib\request.py", line 499, in error
    return self._call_chain(*args)
  File "C:\Python34\lib\urllib\request.py", line 433, in _call_chain
    result = func(*args)
  File "C:\Python34\lib\urllib\request.py", line 579, in http_error_default
    raise HTTPError(req.full_url, code, msg, hdrs, fp)
urllib.error.HTTPError: HTTP Error 404: Not Found
[EXCEPTION] [2015-02-18|10:40:16] URL Error... Timeout?
HTTP Error 404: Not Found
[EXCEPTION] [2015-02-18|10:40:16] Traceback (most recent call last):
  File "C:\Users\PD\Documents\polly\pythonDongle\remote_monitor.py", line 15, in send_request
    wp = urllib2.urlopen(http_request, timeout=d.web_request_timeout)
  File "C:\Python34\lib\urllib\request.py", line 153, in urlopen
    return opener.open(url, data, timeout)
  File "C:\Python34\lib\urllib\request.py", line 461, in open
    response = meth(req, response)
  File "C:\Python34\lib\urllib\request.py", line 571, in http_response
    'http', request, response, code, msg, hdrs)
  File "C:\Python34\lib\urllib\request.py", line 499, in error
    return self._call_chain(*args)
  File "C:\Python34\lib\urllib\request.py", line 433, in _call_chain
    result = func(*args)
  File "C:\Python34\lib\urllib\request.py", line 579, in http_error_default
    raise HTTPError(req.full_url, code, msg, hdrs, fp)
urllib.error.HTTPError: HTTP Error 404: Not Found
[EXCEPTION] [2015-02-18|10:40:16] >>>> Retrying request: http://128.2.211.183/wa/RemoteMonitor/dongleMontiorUpdate.php?update=TE9HO1JTU0k6IDEy
[EXCEPTION] [2015-02-18|10:40:16] URL Error... Timeout?
HTTP Error 404: Not Found
[EXCEPTION] [2015-02-18|10:40:16] Traceback (most recent call last):
  File "C:\Users\PD\Documents\polly\pythonDongle\remote_monitor.py", line 15, in send_request
    wp = urllib2.urlopen(http_request, timeout=d.web_request_timeout)
  File "C:\Python34\lib\urllib\request.py", line 153, in urlopen
    return opener.open(url, data, timeout)
  File "C:\Python34\lib\urllib\request.py", line 461, in open
    response = meth(req, response)
  File "C:\Python34\lib\urllib\request.py", line 571, in http_response
    'http', request, response, code, msg, hdrs)
  File "C:\Python34\lib\urllib\request.py", line 499, in error
    return self._call_chain(*args)
  File "C:\Python34\lib\urllib\request.py", line 433, in _call_chain
    result = func(*args)
  File "C:\Python34\lib\urllib\request.py", line 579, in http_error_default
    raise HTTPError(req.full_url, code, msg, hdrs, fp)
urllib.error.HTTPError: HTTP Error 404: Not Found
[EXCEPTION] [2015-02-18|10:40:16] >>>> Retrying request: http://128.2.211.183/wa/RemoteMonitor/dongleMontiorUpdate.php?update=TE9HO0NBUlJJRVI6IENlbGxjb20gR04=
[EXCEPTION] [2015-02-18|10:40:16] URL Error... Timeout?
HTTP Error 404: Not Found
[EXCEPTION] [2015-02-18|10:40:16] Traceback (most recent call last):
  File "C:\Users\PD\Documents\polly\pythonDongle\remote_monitor.py", line 15, in send_request
    wp = urllib2.urlopen(http_request, timeout=d.web_request_timeout)
  File "C:\Python34\lib\urllib\request.py", line 153, in urlopen
    return opener.open(url, data, timeout)
  File "C:\Python34\lib\urllib\request.py", line 461, in open
    response = meth(req, response)
  File "C:\Python34\lib\urllib\request.py", line 571, in http_response
    'http', request, response, code, msg, hdrs)
  File "C:\Python34\lib\urllib\request.py", line 499, in error
    return self._call_chain(*args)
  File "C:\Python34\lib\urllib\request.py", line 433, in _call_chain
    result = func(*args)
  File "C:\Python34\lib\urllib\request.py", line 579, in http_error_default
    raise HTTPError(req.full_url, code, msg, hdrs, fp)
urllib.error.HTTPError: HTTP Error 404: Not Found
[EXCEPTION] [2015-02-18|10:40:16] URL Error... Timeout?
HTTP Error 404: Not Found
[EXCEPTION] [2015-02-18|10:40:16] Traceback (most recent call last):
  File "C:\Users\PD\Documents\polly\pythonDongle\remote_monitor.py", line 15, in send_request
    wp = urllib2.urlopen(http_request, timeout=d.web_request_timeout)
  File "C:\Python34\lib\urllib\request.py", line 153, in urlopen
    return opener.open(url, data, timeout)
  File "C:\Python34\lib\urllib\request.py", line 461, in open
    response = meth(req, response)
  File "C:\Python34\lib\urllib\request.py", line 571, in http_response
    'http', request, response, code, msg, hdrs)
  File "C:\Python34\lib\urllib\request.py", line 499, in error
    return self._call_chain(*args)
  File "C:\Python34\lib\urllib\request.py", line 433, in _call_chain
    result = func(*args)
  File "C:\Python34\lib\urllib\request.py", line 579, in http_error_default
    raise HTTPError(req.full_url, code, msg, hdrs, fp)
urllib.error.HTTPError: HTTP Error 404: Not Found
[EXCEPTION] [2015-02-18|10:40:16] URL Error... Timeout?
HTTP Error 404: Not Found
[EXCEPTION] [2015-02-18|10:40:16] >>>> Retrying request: http://128.2.211.183/wa/RemoteMonitor/dongleMontiorUpdate.php?update=TE9HOytDU1EgUmVzcG9uc2U6IEFUK0NTUQ0NCitDU1E6IDEyLDk5DQoNCk9LDQo=
[EXCEPTION] [2015-02-18|10:40:16] Traceback (most recent call last):
  File "C:\Users\PD\Documents\polly\pythonDongle\remote_monitor.py", line 15, in send_request
    wp = urllib2.urlopen(http_request, timeout=d.web_request_timeout)
  File "C:\Python34\lib\urllib\request.py", line 153, in urlopen
    return opener.open(url, data, timeout)
  File "C:\Python34\lib\urllib\request.py", line 461, in open
    response = meth(req, response)
  File "C:\Python34\lib\urllib\request.py", line 571, in http_response
    'http', request, response, code, msg, hdrs)
  File "C:\Python34\lib\urllib\request.py", line 499, in error
    return self._call_chain(*args)
  File "C:\Python34\lib\urllib\request.py", line 433, in _call_chain
    result = func(*args)
  File "C:\Python34\lib\urllib\request.py", line 579, in http_error_default
    raise HTTPError(req.full_url, code, msg, hdrs, fp)
urllib.error.HTTPError: HTTP Error 404: Not Found
[EXCEPTION] [2015-02-18|10:40:16] URL Error... Timeout?
HTTP Error 404: Not Found
[EXCEPTION] [2015-02-18|10:40:16] Traceback (most recent call last):
  File "C:\Users\PD\Documents\polly\pythonDongle\remote_monitor.py", line 15, in send_request
    wp = urllib2.urlopen(http_request, timeout=d.web_request_timeout)
  File "C:\Python34\lib\urllib\request.py", line 153, in urlopen
    return opener.open(url, data, timeout)
  File "C:\Python34\lib\urllib\request.py", line 461, in open
    response = meth(req, response)
  File "C:\Python34\lib\urllib\request.py", line 571, in http_response
    'http', request, response, code, msg, hdrs)
  File "C:\Python34\lib\urllib\request.py", line 499, in error
    return self._call_chain(*args)
  File "C:\Python34\lib\urllib\request.py", line 433, in _call_chain
    result = func(*args)
  File "C:\Python34\lib\urllib\request.py", line 579, in http_error_default
    raise HTTPError(req.full_url, code, msg, hdrs, fp)
urllib.error.HTTPError: HTTP Error 404: Not Found
[EXCEPTION] [2015-02-18|10:40:16] >>>> Retrying request: http://128.2.211.183/wa/RemoteMonitor/dongleMontiorUpdate.php?update=TE9HO1JTU0k6IDEy
[EXCEPTION] [2015-02-18|10:40:16] URL Error... Timeout?
HTTP Error 404: Not Found
[EXCEPTION] [2015-02-18|10:40:16] Traceback (most recent call last):
  File "C:\Users\PD\Documents\polly\pythonDongle\remote_monitor.py", line 15, in send_request
    wp = urllib2.urlopen(http_request, timeout=d.web_request_timeout)
  File "C:\Python34\lib\urllib\request.py", line 153, in urlopen
    return opener.open(url, data, timeout)
  File "C:\Python34\lib\urllib\request.py", line 461, in open
    response = meth(req, response)
  File "C:\Python34\lib\urllib\request.py", line 571, in http_response
    'http', request, response, code, msg, hdrs)
  File "C:\Python34\lib\urllib\request.py", line 499, in error
    return self._call_chain(*args)
  File "C:\Python34\lib\urllib\request.py", line 433, in _call_chain
    result = func(*args)
  File "C:\Python34\lib\urllib\request.py", line 579, in http_error_default
    raise HTTPError(req.full_url, code, msg, hdrs, fp)
urllib.error.HTTPError: HTTP Error 404: Not Found
[EXCEPTION] [2015-02-18|10:40:16] >>>> Retrying request: http://128.2.211.183/wa/RemoteMonitor/dongleMontiorUpdate.php?update=TE9HO0NBUlJJRVI6IENlbGxjb20gR04=
[EXCEPTION] [2015-02-18|10:40:17] URL Error... Timeout?
HTTP Error 404: Not Found
[EXCEPTION] [2015-02-18|10:40:17] URL Error... Timeout?
HTTP Error 404: Not Found
[EXCEPTION] [2015-02-18|10:40:17] Traceback (most recent call last):
  File "C:\Users\PD\Documents\polly\pythonDongle\remote_monitor.py", line 15, in send_request
    wp = urllib2.urlopen(http_request, timeout=d.web_request_timeout)
  File "C:\Python34\lib\urllib\request.py", line 153, in urlopen
    return opener.open(url, data, timeout)
  File "C:\Python34\lib\urllib\request.py", line 461, in open
    response = meth(req, response)
  File "C:\Python34\lib\urllib\request.py", line 571, in http_response
    'http', request, response, code, msg, hdrs)
  File "C:\Python34\lib\urllib\request.py", line 499, in error
    return self._call_chain(*args)
  File "C:\Python34\lib\urllib\request.py", line 433, in _call_chain
    result = func(*args)
  File "C:\Python34\lib\urllib\request.py", line 579, in http_error_default
    raise HTTPError(req.full_url, code, msg, hdrs, fp)
urllib.error.HTTPError: HTTP Error 404: Not Found
[EXCEPTION] [2015-02-18|10:40:17] Traceback (most recent call last):
  File "C:\Users\PD\Documents\polly\pythonDongle\remote_monitor.py", line 15, in send_request
    wp = urllib2.urlopen(http_request, timeout=d.web_request_timeout)
  File "C:\Python34\lib\urllib\request.py", line 153, in urlopen
    return opener.open(url, data, timeout)
  File "C:\Python34\lib\urllib\request.py", line 461, in open
    response = meth(req, response)
  File "C:\Python34\lib\urllib\request.py", line 571, in http_response
    'http', request, response, code, msg, hdrs)
  File "C:\Python34\lib\urllib\request.py", line 499, in error
    return self._call_chain(*args)
  File "C:\Python34\lib\urllib\request.py", line 433, in _call_chain
    result = func(*args)
  File "C:\Python34\lib\urllib\request.py", line 579, in http_error_default
    raise HTTPError(req.full_url, code, msg, hdrs, fp)
urllib.error.HTTPError: HTTP Error 404: Not Found
[EXCEPTION] [2015-02-18|10:40:17] URL Error... Timeout?
HTTP Error 404: Not Found
[EXCEPTION] [2015-02-18|10:40:17] Traceback (most recent call last):
  File "C:\Users\PD\Documents\polly\pythonDongle\remote_monitor.py", line 15, in send_request
    wp = urllib2.urlopen(http_request, timeout=d.web_request_timeout)
  File "C:\Python34\lib\urllib\request.py", line 153, in urlopen
    return opener.open(url, data, timeout)
  File "C:\Python34\lib\urllib\request.py", line 461, in open
    response = meth(req, response)
  File "C:\Python34\lib\urllib\request.py", line 571, in http_response
    'http', request, response, code, msg, hdrs)
  File "C:\Python34\lib\urllib\request.py", line 499, in error
    return self._call_chain(*args)
  File "C:\Python34\lib\urllib\request.py", line 433, in _call_chain
    result = func(*args)
  File "C:\Python34\lib\urllib\request.py", line 579, in http_error_default
    raise HTTPError(req.full_url, code, msg, hdrs, fp)
urllib.error.HTTPError: HTTP Error 404: Not Found
[EXCEPTION] [2015-02-18|10:40:17] >>>> Retrying request: http://128.2.211.183/wa/RemoteMonitor/dongleMontiorUpdate.php?update=TE9HOytDUEFTIFJlc3BvbnNlOiBBVCtDUEFTDQ0KK0NQQVM6IDANCg0KT0sNCg==
[EXCEPTION] [2015-02-18|10:40:17] URL Error... Timeout?
HTTP Error 404: Not Found
[EXCEPTION] [2015-02-18|10:40:17] >>>> Retrying request: http://128.2.211.183/wa/RemoteMonitor/dongleMontiorUpdate.php?update=QUxJVkU7WzIwMTUtMDItMTh8MTA6NDA6MTRdOzE7MTI7Q2VsbGNvbSBHTjtSRUFEWTtDT00yMA==
[EXCEPTION] [2015-02-18|10:40:17] Traceback (most recent call last):
  File "C:\Users\PD\Documents\polly\pythonDongle\remote_monitor.py", line 15, in send_request
    wp = urllib2.urlopen(http_request, timeout=d.web_request_timeout)
  File "C:\Python34\lib\urllib\request.py", line 153, in urlopen
    return opener.open(url, data, timeout)
  File "C:\Python34\lib\urllib\request.py", line 461, in open
    response = meth(req, response)
  File "C:\Python34\lib\urllib\request.py", line 571, in http_response
    'http', request, response, code, msg, hdrs)
  File "C:\Python34\lib\urllib\request.py", line 499, in error
    return self._call_chain(*args)
  File "C:\Python34\lib\urllib\request.py", line 433, in _call_chain
    result = func(*args)
  File "C:\Python34\lib\urllib\request.py", line 579, in http_error_default
    raise HTTPError(req.full_url, code, msg, hdrs, fp)
urllib.error.HTTPError: HTTP Error 404: Not Found
[EXCEPTION] [2015-02-18|10:40:17] URL Error... Timeout?
HTTP Error 404: Not Found
[EXCEPTION] [2015-02-18|10:40:17] >>>> Retrying request: http://128.2.211.183/wa/RemoteMonitor/dongleMontiorUpdate.php?update=TE9HOytDU1EgUmVzcG9uc2U6IEFUK0NTUQ0NCitDU1E6IDEyLDk5DQoNCk9LDQo=
[EXCEPTION] [2015-02-18|10:40:17] Traceback (most recent call last):
  File "C:\Users\PD\Documents\polly\pythonDongle\remote_monitor.py", line 15, in send_request
    wp = urllib2.urlopen(http_request, timeout=d.web_request_timeout)
  File "C:\Python34\lib\urllib\request.py", line 153, in urlopen
    return opener.open(url, data, timeout)
  File "C:\Python34\lib\urllib\request.py", line 461, in open
    response = meth(req, response)
  File "C:\Python34\lib\urllib\request.py", line 571, in http_response
    'http', request, response, code, msg, hdrs)
  File "C:\Python34\lib\urllib\request.py", line 499, in error
    return self._call_chain(*args)
  File "C:\Python34\lib\urllib\request.py", line 433, in _call_chain
    result = func(*args)
  File "C:\Python34\lib\urllib\request.py", line 579, in http_error_default
    raise HTTPError(req.full_url, code, msg, hdrs, fp)
urllib.error.HTTPError: HTTP Error 404: Not Found
[EXCEPTION] [2015-02-18|10:40:17] URL Error... Timeout?
HTTP Error 404: Not Found
[EXCEPTION] [2015-02-18|10:40:17] URL Error... Timeout?
HTTP Error 404: Not Found
[EXCEPTION] [2015-02-18|10:40:17] URL Error... Timeout?
HTTP Error 404: Not Found
[EXCEPTION] [2015-02-18|10:40:17] Traceback (most recent call last):
  File "C:\Users\PD\Documents\polly\pythonDongle\remote_monitor.py", line 15, in send_request
    wp = urllib2.urlopen(http_request, timeout=d.web_request_timeout)
  File "C:\Python34\lib\urllib\request.py", line 153, in urlopen
    return opener.open(url, data, timeout)
  File "C:\Python34\lib\urllib\request.py", line 461, in open
    response = meth(req, response)
  File "C:\Python34\lib\urllib\request.py", line 571, in http_response
    'http', request, response, code, msg, hdrs)
  File "C:\Python34\lib\urllib\request.py", line 499, in error
    return self._call_chain(*args)
  File "C:\Python34\lib\urllib\request.py", line 433, in _call_chain
    result = func(*args)
  File "C:\Python34\lib\urllib\request.py", line 579, in http_error_default
    raise HTTPError(req.full_url, code, msg, hdrs, fp)
urllib.error.HTTPError: HTTP Error 404: Not Found
[EXCEPTION] [2015-02-18|10:40:17] Traceback (most recent call last):
  File "C:\Users\PD\Documents\polly\pythonDongle\remote_monitor.py", line 15, in send_request
    wp = urllib2.urlopen(http_request, timeout=d.web_request_timeout)
  File "C:\Python34\lib\urllib\request.py", line 153, in urlopen
    return opener.open(url, data, timeout)
  File "C:\Python34\lib\urllib\request.py", line 461, in open
    response = meth(req, response)
  File "C:\Python34\lib\urllib\request.py", line 571, in http_response
    'http', request, response, code, msg, hdrs)
  File "C:\Python34\lib\urllib\request.py", line 499, in error
    return self._call_chain(*args)
  File "C:\Python34\lib\urllib\request.py", line 433, in _call_chain
    result = func(*args)
  File "C:\Python34\lib\urllib\request.py", line 579, in http_error_default
    raise HTTPError(req.full_url, code, msg, hdrs, fp)
urllib.error.HTTPError: HTTP Error 404: Not Found
[EXCEPTION] [2015-02-18|10:40:17] URL Error... Timeout?
HTTP Error 404: Not Found
[EXCEPTION] [2015-02-18|10:40:17] Traceback (most recent call last):
  File "C:\Users\PD\Documents\polly\pythonDongle\remote_monitor.py", line 15, in send_request
    wp = urllib2.urlopen(http_request, timeout=d.web_request_timeout)
  File "C:\Python34\lib\urllib\request.py", line 153, in urlopen
    return opener.open(url, data, timeout)
  File "C:\Python34\lib\urllib\request.py", line 461, in open
    response = meth(req, response)
  File "C:\Python34\lib\urllib\request.py", line 571, in http_response
    'http', request, response, code, msg, hdrs)
  File "C:\Python34\lib\urllib\request.py", line 499, in error
    return self._call_chain(*args)
  File "C:\Python34\lib\urllib\request.py", line 433, in _call_chain
    result = func(*args)
  File "C:\Python34\lib\urllib\request.py", line 579, in http_error_default
    raise HTTPError(req.full_url, code, msg, hdrs, fp)
urllib.error.HTTPError: HTTP Error 404: Not Found
[EXCEPTION] [2015-02-18|10:40:17] Traceback (most recent call last):
  File "C:\Users\PD\Documents\polly\pythonDongle\remote_monitor.py", line 15, in send_request
    wp = urllib2.urlopen(http_request, timeout=d.web_request_timeout)
  File "C:\Python34\lib\urllib\request.py", line 153, in urlopen
    return opener.open(url, data, timeout)
  File "C:\Python34\lib\urllib\request.py", line 461, in open
    response = meth(req, response)
  File "C:\Python34\lib\urllib\request.py", line 571, in http_response
    'http', request, response, code, msg, hdrs)
  File "C:\Python34\lib\urllib\request.py", line 499, in error
    return self._call_chain(*args)
  File "C:\Python34\lib\urllib\request.py", line 433, in _call_chain
    result = func(*args)
  File "C:\Python34\lib\urllib\request.py", line 579, in http_error_default
    raise HTTPError(req.full_url, code, msg, hdrs, fp)
urllib.error.HTTPError: HTTP Error 404: Not Found
[EXCEPTION] [2015-02-18|10:40:17] >>>> Retrying request: http://128.2.211.183/wa/RemoteMonitor/dongleMontiorUpdate.php?update=TE9HOytDU1EgUmVzcG9uc2U6IEFUK0NTUQ0NCitDU1E6IDEyLDk5DQoNCk9LDQo=
[EXCEPTION] [2015-02-18|10:40:17] URL Error... Timeout?
HTTP Error 404: Not Found
[EXCEPTION] [2015-02-18|10:40:17] Traceback (most recent call last):
  File "C:\Users\PD\Documents\polly\pythonDongle\remote_monitor.py", line 15, in send_request
    wp = urllib2.urlopen(http_request, timeout=d.web_request_timeout)
  File "C:\Python34\lib\urllib\request.py", line 153, in urlopen
    return opener.open(url, data, timeout)
  File "C:\Python34\lib\urllib\request.py", line 461, in open
    response = meth(req, response)
  File "C:\Python34\lib\urllib\request.py", line 571, in http_response
    'http', request, response, code, msg, hdrs)
  File "C:\Python34\lib\urllib\request.py", line 499, in error
    return self._call_chain(*args)
  File "C:\Python34\lib\urllib\request.py", line 433, in _call_chain
    result = func(*args)
  File "C:\Python34\lib\urllib\request.py", line 579, in http_error_default
    raise HTTPError(req.full_url, code, msg, hdrs, fp)
urllib.error.HTTPError: HTTP Error 404: Not Found
[EXCEPTION] [2015-02-18|10:40:17] >>>> Retrying request: http://128.2.211.183/wa/RemoteMonitor/dongleMontiorUpdate.php?update=TE9HO1JTU0k6IDEy
[EXCEPTION] [2015-02-18|10:40:17] URL Error... Timeout?
HTTP Error 404: Not Found
[EXCEPTION] [2015-02-18|10:40:17] Traceback (most recent call last):
  File "C:\Users\PD\Documents\polly\pythonDongle\remote_monitor.py", line 15, in send_request
    wp = urllib2.urlopen(http_request, timeout=d.web_request_timeout)
  File "C:\Python34\lib\urllib\request.py", line 153, in urlopen
    return opener.open(url, data, timeout)
  File "C:\Python34\lib\urllib\request.py", line 461, in open
    response = meth(req, response)
  File "C:\Python34\lib\urllib\request.py", line 571, in http_response
    'http', request, response, code, msg, hdrs)
  File "C:\Python34\lib\urllib\request.py", line 499, in error
    return self._call_chain(*args)
  File "C:\Python34\lib\urllib\request.py", line 433, in _call_chain
    result = func(*args)
  File "C:\Python34\lib\urllib\request.py", line 579, in http_error_default
    raise HTTPError(req.full_url, code, msg, hdrs, fp)
urllib.error.HTTPError: HTTP Error 404: Not Found
[EXCEPTION] [2015-02-18|10:40:17] URL Error... Timeout?
HTTP Error 404: Not Found
[EXCEPTION] [2015-02-18|10:40:17] URL Error... Timeout?
HTTP Error 404: Not Found
[EXCEPTION] [2015-02-18|10:40:17] Traceback (most recent call last):
  File "C:\Users\PD\Documents\polly\pythonDongle\remote_monitor.py", line 15, in send_request
    wp = urllib2.urlopen(http_request, timeout=d.web_request_timeout)
  File "C:\Python34\lib\urllib\request.py", line 153, in urlopen
    return opener.open(url, data, timeout)
  File "C:\Python34\lib\urllib\request.py", line 461, in open
    response = meth(req, response)
  File "C:\Python34\lib\urllib\request.py", line 571, in http_response
    'http', request, response, code, msg, hdrs)
  File "C:\Python34\lib\urllib\request.py", line 499, in error
    return self._call_chain(*args)
  File "C:\Python34\lib\urllib\request.py", line 433, in _call_chain
    result = func(*args)
  File "C:\Python34\lib\urllib\request.py", line 579, in http_error_default
    raise HTTPError(req.full_url, code, msg, hdrs, fp)
urllib.error.HTTPError: HTTP Error 404: Not Found
[EXCEPTION] [2015-02-18|10:40:17] >>>> Retrying request: http://128.2.211.183/wa/RemoteMonitor/dongleMontiorUpdate.php?update=TE9HO0NBUlJJRVI6IENlbGxjb20gR04=
[EXCEPTION] [2015-02-18|10:40:17] Traceback (most recent call last):
  File "C:\Users\PD\Documents\polly\pythonDongle\remote_monitor.py", line 15, in send_request
    wp = urllib2.urlopen(http_request, timeout=d.web_request_timeout)
  File "C:\Python34\lib\urllib\request.py", line 153, in urlopen
    return opener.open(url, data, timeout)
  File "C:\Python34\lib\urllib\request.py", line 461, in open
    response = meth(req, response)
  File "C:\Python34\lib\urllib\request.py", line 571, in http_response
    'http', request, response, code, msg, hdrs)
  File "C:\Python34\lib\urllib\request.py", line 499, in error
    return self._call_chain(*args)
  File "C:\Python34\lib\urllib\request.py", line 433, in _call_chain
    result = func(*args)
  File "C:\Python34\lib\urllib\request.py", line 579, in http_error_default
    raise HTTPError(req.full_url, code, msg, hdrs, fp)
urllib.error.HTTPError: HTTP Error 404: Not Found
[EXCEPTION] [2015-02-18|10:40:17] URL Error... Timeout?
HTTP Error 404: Not Found
[EXCEPTION] [2015-02-18|10:40:17] >>>> Retrying request: http://128.2.211.183/wa/RemoteMonitor/dongleMontiorUpdate.php?update=TE9HOytDUEFTIFJlc3BvbnNlOiBBVCtDUEFTDQ0KK0NQQVM6IDANCg0KT0sNCg==
[EXCEPTION] [2015-02-18|10:40:18] URL Error... Timeout?
HTTP Error 404: Not Found
[EXCEPTION] [2015-02-18|10:40:18] Traceback (most recent call last):
  File "C:\Users\PD\Documents\polly\pythonDongle\remote_monitor.py", line 15, in send_request
    wp = urllib2.urlopen(http_request, timeout=d.web_request_timeout)
  File "C:\Python34\lib\urllib\request.py", line 153, in urlopen
    return opener.open(url, data, timeout)
  File "C:\Python34\lib\urllib\request.py", line 461, in open
    response = meth(req, response)
  File "C:\Python34\lib\urllib\request.py", line 571, in http_response
    'http', request, response, code, msg, hdrs)
  File "C:\Python34\lib\urllib\request.py", line 499, in error
    return self._call_chain(*args)
  File "C:\Python34\lib\urllib\request.py", line 433, in _call_chain
    result = func(*args)
  File "C:\Python34\lib\urllib\request.py", line 579, in http_error_default
    raise HTTPError(req.full_url, code, msg, hdrs, fp)
urllib.error.HTTPError: HTTP Error 404: Not Found
[EXCEPTION] [2015-02-18|10:40:18] URL Error... Timeout?
HTTP Error 404: Not Found
[EXCEPTION] [2015-02-18|10:40:18] >>>> Retrying request: http://128.2.211.183/wa/RemoteMonitor/dongleMontiorUpdate.php?update=TE9HO0RFVklDRSBTVEFURTogUkVBRFk=
[EXCEPTION] [2015-02-18|10:40:18] Traceback (most recent call last):
  File "C:\Users\PD\Documents\polly\pythonDongle\remote_monitor.py", line 15, in send_request
    wp = urllib2.urlopen(http_request, timeout=d.web_request_timeout)
  File "C:\Python34\lib\urllib\request.py", line 153, in urlopen
    return opener.open(url, data, timeout)
  File "C:\Python34\lib\urllib\request.py", line 461, in open
    response = meth(req, response)
  File "C:\Python34\lib\urllib\request.py", line 571, in http_response
    'http', request, response, code, msg, hdrs)
  File "C:\Python34\lib\urllib\request.py", line 499, in error
    return self._call_chain(*args)
  File "C:\Python34\lib\urllib\request.py", line 433, in _call_chain
    result = func(*args)
  File "C:\Python34\lib\urllib\request.py", line 579, in http_error_default
    raise HTTPError(req.full_url, code, msg, hdrs, fp)
urllib.error.HTTPError: HTTP Error 404: Not Found
[EXCEPTION] [2015-02-18|10:40:18] URL Error... Timeout?
HTTP Error 404: Not Found
[EXCEPTION] [2015-02-18|10:40:18] >>>> Retrying request: http://128.2.211.183/wa/RemoteMonitor/dongleMontiorUpdate.php?update=TE9HO0NBUlJJRVI6IENlbGxjb20gR04=
[EXCEPTION] [2015-02-18|10:40:18] Traceback (most recent call last):
  File "C:\Users\PD\Documents\polly\pythonDongle\remote_monitor.py", line 15, in send_request
    wp = urllib2.urlopen(http_request, timeout=d.web_request_timeout)
  File "C:\Python34\lib\urllib\request.py", line 153, in urlopen
    return opener.open(url, data, timeout)
  File "C:\Python34\lib\urllib\request.py", line 461, in open
    response = meth(req, response)
  File "C:\Python34\lib\urllib\request.py", line 571, in http_response
    'http', request, response, code, msg, hdrs)
  File "C:\Python34\lib\urllib\request.py", line 499, in error
    return self._call_chain(*args)
  File "C:\Python34\lib\urllib\request.py", line 433, in _call_chain
    result = func(*args)
  File "C:\Python34\lib\urllib\request.py", line 579, in http_error_default
    raise HTTPError(req.full_url, code, msg, hdrs, fp)
urllib.error.HTTPError: HTTP Error 404: Not Found
[EXCEPTION] [2015-02-18|10:40:18] URL Error... Timeout?
HTTP Error 404: Not Found
[EXCEPTION] [2015-02-18|10:40:18] Traceback (most recent call last):
  File "C:\Users\PD\Documents\polly\pythonDongle\remote_monitor.py", line 15, in send_request
    wp = urllib2.urlopen(http_request, timeout=d.web_request_timeout)
  File "C:\Python34\lib\urllib\request.py", line 153, in urlopen
    return opener.open(url, data, timeout)
  File "C:\Python34\lib\urllib\request.py", line 461, in open
    response = meth(req, response)
  File "C:\Python34\lib\urllib\request.py", line 571, in http_response
    'http', request, response, code, msg, hdrs)
  File "C:\Python34\lib\urllib\request.py", line 499, in error
    return self._call_chain(*args)
  File "C:\Python34\lib\urllib\request.py", line 433, in _call_chain
    result = func(*args)
  File "C:\Python34\lib\urllib\request.py", line 579, in http_error_default
    raise HTTPError(req.full_url, code, msg, hdrs, fp)
urllib.error.HTTPError: HTTP Error 404: Not Found
[EXCEPTION] [2015-02-18|10:40:18] Traceback (most recent call last):
  File "C:\Users\PD\Documents\polly\pythonDongle\remote_monitor.py", line 15, in send_request
    wp = urllib2.urlopen(http_request, timeout=d.web_request_timeout)
  File "C:\Python34\lib\urllib\request.py", line 153, in urlopen
    return opener.open(url, data, timeout)
  File "C:\Python34\lib\urllib\request.py", line 461, in open
    response = meth(req, response)
  File "C:\Python34\lib\urllib\request.py", line 571, in http_response
    'http', request, response, code, msg, hdrs)
  File "C:\Python34\lib\urllib\request.py", line 499, in error
    return self._call_chain(*args)
  File "C:\Python34\lib\urllib\request.py", line 433, in _call_chain
    result = func(*args)
  File "C:\Python34\lib\urllib\request.py", line 579, in http_error_default
    raise HTTPError(req.full_url, code, msg, hdrs, fp)
urllib.error.HTTPError: HTTP Error 404: Not Found
[EXCEPTION] [2015-02-18|10:40:18] URL Error... Timeout?
HTTP Error 404: Not Found
[EXCEPTION] [2015-02-18|10:40:18] URL Error... Timeout?
HTTP Error 404: Not Found
[EXCEPTION] [2015-02-18|10:40:18] Traceback (most recent call last):
  File "C:\Users\PD\Documents\polly\pythonDongle\remote_monitor.py", line 15, in send_request
    wp = urllib2.urlopen(http_request, timeout=d.web_request_timeout)
  File "C:\Python34\lib\urllib\request.py", line 153, in urlopen
    return opener.open(url, data, timeout)
  File "C:\Python34\lib\urllib\request.py", line 461, in open
    response = meth(req, response)
  File "C:\Python34\lib\urllib\request.py", line 571, in http_response
    'http', request, response, code, msg, hdrs)
  File "C:\Python34\lib\urllib\request.py", line 499, in error
    return self._call_chain(*args)
  File "C:\Python34\lib\urllib\request.py", line 433, in _call_chain
    result = func(*args)
  File "C:\Python34\lib\urllib\request.py", line 579, in http_error_default
    raise HTTPError(req.full_url, code, msg, hdrs, fp)
urllib.error.HTTPError: HTTP Error 404: Not Found
[EXCEPTION] [2015-02-18|10:40:18] URL Error... Timeout?
HTTP Error 404: Not Found
[EXCEPTION] [2015-02-18|10:40:18] Traceback (most recent call last):
  File "C:\Users\PD\Documents\polly\pythonDongle\remote_monitor.py", line 15, in send_request
    wp = urllib2.urlopen(http_request, timeout=d.web_request_timeout)
  File "C:\Python34\lib\urllib\request.py", line 153, in urlopen
    return opener.open(url, data, timeout)
  File "C:\Python34\lib\urllib\request.py", line 461, in open
    response = meth(req, response)
  File "C:\Python34\lib\urllib\request.py", line 571, in http_response
    'http', request, response, code, msg, hdrs)
  File "C:\Python34\lib\urllib\request.py", line 499, in error
    return self._call_chain(*args)
  File "C:\Python34\lib\urllib\request.py", line 433, in _call_chain
    result = func(*args)
  File "C:\Python34\lib\urllib\request.py", line 579, in http_error_default
    raise HTTPError(req.full_url, code, msg, hdrs, fp)
urllib.error.HTTPError: HTTP Error 404: Not Found
[EXCEPTION] [2015-02-18|10:40:18] >>>> Retrying request: http://128.2.211.183/wa/RemoteMonitor/dongleMontiorUpdate.php?update=QUxJVkU7WzIwMTUtMDItMTh8MTA6NDA6MTRdOzE7MTI7Q2VsbGNvbSBHTjtSRUFEWTtDT00yMA==
[EXCEPTION] [2015-02-18|10:40:18] >>>> Retrying request: http://128.2.211.183/wa/RemoteMonitor/dongleMontiorUpdate.php?update=TE9HOytDUEFTIFJlc3BvbnNlOiBBVCtDUEFTDQ0KK0NQQVM6IDANCg0KT0sNCg==
[EXCEPTION] [2015-02-18|10:40:18] Traceback (most recent call last):
  File "C:\Users\PD\Documents\polly\pythonDongle\remote_monitor.py", line 15, in send_request
    wp = urllib2.urlopen(http_request, timeout=d.web_request_timeout)
  File "C:\Python34\lib\urllib\request.py", line 153, in urlopen
    return opener.open(url, data, timeout)
  File "C:\Python34\lib\urllib\request.py", line 461, in open
    response = meth(req, response)
  File "C:\Python34\lib\urllib\request.py", line 571, in http_response
    'http', request, response, code, msg, hdrs)
  File "C:\Python34\lib\urllib\request.py", line 499, in error
    return self._call_chain(*args)
  File "C:\Python34\lib\urllib\request.py", line 433, in _call_chain
    result = func(*args)
  File "C:\Python34\lib\urllib\request.py", line 579, in http_error_default
    raise HTTPError(req.full_url, code, msg, hdrs, fp)
urllib.error.HTTPError: HTTP Error 404: Not Found
[EXCEPTION] [2015-02-18|10:40:18] URL Error... Timeout?
HTTP Error 404: Not Found
[EXCEPTION] [2015-02-18|10:40:18] Traceback (most recent call last):
  File "C:\Users\PD\Documents\polly\pythonDongle\remote_monitor.py", line 15, in send_request
    wp = urllib2.urlopen(http_request, timeout=d.web_request_timeout)
  File "C:\Python34\lib\urllib\request.py", line 153, in urlopen
    return opener.open(url, data, timeout)
  File "C:\Python34\lib\urllib\request.py", line 461, in open
    response = meth(req, response)
  File "C:\Python34\lib\urllib\request.py", line 571, in http_response
    'http', request, response, code, msg, hdrs)
  File "C:\Python34\lib\urllib\request.py", line 499, in error
    return self._call_chain(*args)
  File "C:\Python34\lib\urllib\request.py", line 433, in _call_chain
    result = func(*args)
  File "C:\Python34\lib\urllib\request.py", line 579, in http_error_default
    raise HTTPError(req.full_url, code, msg, hdrs, fp)
urllib.error.HTTPError: HTTP Error 404: Not Found
[EXCEPTION] [2015-02-18|10:40:18] URL Error... Timeout?
HTTP Error 404: Not Found
[EXCEPTION] [2015-02-18|10:40:18] URL Error... Timeout?
HTTP Error 404: Not Found
[EXCEPTION] [2015-02-18|10:40:18] Traceback (most recent call last):
  File "C:\Users\PD\Documents\polly\pythonDongle\remote_monitor.py", line 15, in send_request
    wp = urllib2.urlopen(http_request, timeout=d.web_request_timeout)
  File "C:\Python34\lib\urllib\request.py", line 153, in urlopen
    return opener.open(url, data, timeout)
  File "C:\Python34\lib\urllib\request.py", line 461, in open
    response = meth(req, response)
  File "C:\Python34\lib\urllib\request.py", line 571, in http_response
    'http', request, response, code, msg, hdrs)
  File "C:\Python34\lib\urllib\request.py", line 499, in error
    return self._call_chain(*args)
  File "C:\Python34\lib\urllib\request.py", line 433, in _call_chain
    result = func(*args)
  File "C:\Python34\lib\urllib\request.py", line 579, in http_error_default
    raise HTTPError(req.full_url, code, msg, hdrs, fp)
urllib.error.HTTPError: HTTP Error 404: Not Found
[EXCEPTION] [2015-02-18|10:40:18] Traceback (most recent call last):
  File "C:\Users\PD\Documents\polly\pythonDongle\remote_monitor.py", line 15, in send_request
    wp = urllib2.urlopen(http_request, timeout=d.web_request_timeout)
  File "C:\Python34\lib\urllib\request.py", line 153, in urlopen
    return opener.open(url, data, timeout)
  File "C:\Python34\lib\urllib\request.py", line 461, in open
    response = meth(req, response)
  File "C:\Python34\lib\urllib\request.py", line 571, in http_response
    'http', request, response, code, msg, hdrs)
  File "C:\Python34\lib\urllib\request.py", line 499, in error
    return self._call_chain(*args)
  File "C:\Python34\lib\urllib\request.py", line 433, in _call_chain
    result = func(*args)
  File "C:\Python34\lib\urllib\request.py", line 579, in http_error_default
    raise HTTPError(req.full_url, code, msg, hdrs, fp)
urllib.error.HTTPError: HTTP Error 404: Not Found
[EXCEPTION] [2015-02-18|10:40:18] >>>> Retrying request: http://128.2.211.183/wa/RemoteMonitor/dongleMontiorUpdate.php?update=TE9HO1JTU0k6IDEy
[EXCEPTION] [2015-02-18|10:40:18] URL Error... Timeout?
HTTP Error 404: Not Found
[EXCEPTION] [2015-02-18|10:40:18] URL Error... Timeout?
HTTP Error 404: Not Found
[EXCEPTION] [2015-02-18|10:40:18] Traceback (most recent call last):
  File "C:\Users\PD\Documents\polly\pythonDongle\remote_monitor.py", line 15, in send_request
    wp = urllib2.urlopen(http_request, timeout=d.web_request_timeout)
  File "C:\Python34\lib\urllib\request.py", line 153, in urlopen
    return opener.open(url, data, timeout)
  File "C:\Python34\lib\urllib\request.py", line 461, in open
    response = meth(req, response)
  File "C:\Python34\lib\urllib\request.py", line 571, in http_response
    'http', request, response, code, msg, hdrs)
  File "C:\Python34\lib\urllib\request.py", line 499, in error
    return self._call_chain(*args)
  File "C:\Python34\lib\urllib\request.py", line 433, in _call_chain
    result = func(*args)
  File "C:\Python34\lib\urllib\request.py", line 579, in http_error_default
    raise HTTPError(req.full_url, code, msg, hdrs, fp)
urllib.error.HTTPError: HTTP Error 404: Not Found
[EXCEPTION] [2015-02-18|10:40:18] Traceback (most recent call last):
  File "C:\Users\PD\Documents\polly\pythonDongle\remote_monitor.py", line 15, in send_request
    wp = urllib2.urlopen(http_request, timeout=d.web_request_timeout)
  File "C:\Python34\lib\urllib\request.py", line 153, in urlopen
    return opener.open(url, data, timeout)
  File "C:\Python34\lib\urllib\request.py", line 461, in open
    response = meth(req, response)
  File "C:\Python34\lib\urllib\request.py", line 571, in http_response
    'http', request, response, code, msg, hdrs)
  File "C:\Python34\lib\urllib\request.py", line 499, in error
    return self._call_chain(*args)
  File "C:\Python34\lib\urllib\request.py", line 433, in _call_chain
    result = func(*args)
  File "C:\Python34\lib\urllib\request.py", line 579, in http_error_default
    raise HTTPError(req.full_url, code, msg, hdrs, fp)
urllib.error.HTTPError: HTTP Error 404: Not Found
[EXCEPTION] [2015-02-18|10:40:18] >>>> Retrying request: http://128.2.211.183/wa/RemoteMonitor/dongleMontiorUpdate.php?update=TE9HOytDUEFTIFJlc3BvbnNlOiBBVCtDUEFTDQ0KK0NQQVM6IDANCg0KT0sNCg==
[EXCEPTION] [2015-02-18|10:40:18] >>>> Retrying request: http://128.2.211.183/wa/RemoteMonitor/dongleMontiorUpdate.php?update=TE9HO0RFVklDRSBTVEFURTogUkVBRFk=
[EXCEPTION] [2015-02-18|10:40:18] >>>> Retrying request: http://128.2.211.183/wa/RemoteMonitor/dongleMontiorUpdate.php?update=QUxJVkU7WzIwMTUtMDItMTh8MTA6NDA6MTVdOzE7MTI7Q2VsbGNvbSBHTjtSRUFEWTtDT00xNw==
[EXCEPTION] [2015-02-18|10:40:18] URL Error... Timeout?
HTTP Error 404: Not Found
[EXCEPTION] [2015-02-18|10:40:18] URL Error... Timeout?
HTTP Error 404: Not Found
[EXCEPTION] [2015-02-18|10:40:18] URL Error... Timeout?
HTTP Error 404: Not Found
[EXCEPTION] [2015-02-18|10:40:18] Traceback (most recent call last):
  File "C:\Users\PD\Documents\polly\pythonDongle\remote_monitor.py", line 15, in send_request
    wp = urllib2.urlopen(http_request, timeout=d.web_request_timeout)
  File "C:\Python34\lib\urllib\request.py", line 153, in urlopen
    return opener.open(url, data, timeout)
  File "C:\Python34\lib\urllib\request.py", line 461, in open
    response = meth(req, response)
  File "C:\Python34\lib\urllib\request.py", line 571, in http_response
    'http', request, response, code, msg, hdrs)
  File "C:\Python34\lib\urllib\request.py", line 499, in error
    return self._call_chain(*args)
  File "C:\Python34\lib\urllib\request.py", line 433, in _call_chain
    result = func(*args)
  File "C:\Python34\lib\urllib\request.py", line 579, in http_error_default
    raise HTTPError(req.full_url, code, msg, hdrs, fp)
urllib.error.HTTPError: HTTP Error 404: Not Found
[EXCEPTION] [2015-02-18|10:40:18] Traceback (most recent call last):
  File "C:\Users\PD\Documents\polly\pythonDongle\remote_monitor.py", line 15, in send_request
    wp = urllib2.urlopen(http_request, timeout=d.web_request_timeout)
  File "C:\Python34\lib\urllib\request.py", line 153, in urlopen
    return opener.open(url, data, timeout)
  File "C:\Python34\lib\urllib\request.py", line 461, in open
    response = meth(req, response)
  File "C:\Python34\lib\urllib\request.py", line 571, in http_response
    'http', request, response, code, msg, hdrs)
  File "C:\Python34\lib\urllib\request.py", line 499, in error
    return self._call_chain(*args)
  File "C:\Python34\lib\urllib\request.py", line 433, in _call_chain
    result = func(*args)
  File "C:\Python34\lib\urllib\request.py", line 579, in http_error_default
    raise HTTPError(req.full_url, code, msg, hdrs, fp)
urllib.error.HTTPError: HTTP Error 404: Not Found
[EXCEPTION] [2015-02-18|10:40:18] Traceback (most recent call last):
  File "C:\Users\PD\Documents\polly\pythonDongle\remote_monitor.py", line 15, in send_request
    wp = urllib2.urlopen(http_request, timeout=d.web_request_timeout)
  File "C:\Python34\lib\urllib\request.py", line 153, in urlopen
    return opener.open(url, data, timeout)
  File "C:\Python34\lib\urllib\request.py", line 461, in open
    response = meth(req, response)
  File "C:\Python34\lib\urllib\request.py", line 571, in http_response
    'http', request, response, code, msg, hdrs)
  File "C:\Python34\lib\urllib\request.py", line 499, in error
    return self._call_chain(*args)
  File "C:\Python34\lib\urllib\request.py", line 433, in _call_chain
    result = func(*args)
  File "C:\Python34\lib\urllib\request.py", line 579, in http_error_default
    raise HTTPError(req.full_url, code, msg, hdrs, fp)
urllib.error.HTTPError: HTTP Error 404: Not Found
[EXCEPTION] [2015-02-18|10:40:18] >>>> Retrying request: http://128.2.211.183/wa/RemoteMonitor/dongleMontiorUpdate.php?update=TE9HO0NBUlJJRVI6IENlbGxjb20gR04=
[EXCEPTION] [2015-02-18|10:40:19] URL Error... Timeout?
HTTP Error 404: Not Found
[EXCEPTION] [2015-02-18|10:40:19] URL Error... Timeout?
HTTP Error 404: Not Found
[EXCEPTION] [2015-02-18|10:40:19] Traceback (most recent call last):
  File "C:\Users\PD\Documents\polly\pythonDongle\remote_monitor.py", line 15, in send_request
    wp = urllib2.urlopen(http_request, timeout=d.web_request_timeout)
  File "C:\Python34\lib\urllib\request.py", line 153, in urlopen
    return opener.open(url, data, timeout)
  File "C:\Python34\lib\urllib\request.py", line 461, in open
    response = meth(req, response)
  File "C:\Python34\lib\urllib\request.py", line 571, in http_response
    'http', request, response, code, msg, hdrs)
  File "C:\Python34\lib\urllib\request.py", line 499, in error
    return self._call_chain(*args)
  File "C:\Python34\lib\urllib\request.py", line 433, in _call_chain
    result = func(*args)
  File "C:\Python34\lib\urllib\request.py", line 579, in http_error_default
    raise HTTPError(req.full_url, code, msg, hdrs, fp)
urllib.error.HTTPError: HTTP Error 404: Not Found
[EXCEPTION] [2015-02-18|10:40:19] Traceback (most recent call last):
  File "C:\Users\PD\Documents\polly\pythonDongle\remote_monitor.py", line 15, in send_request
    wp = urllib2.urlopen(http_request, timeout=d.web_request_timeout)
  File "C:\Python34\lib\urllib\request.py", line 153, in urlopen
    return opener.open(url, data, timeout)
  File "C:\Python34\lib\urllib\request.py", line 461, in open
    response = meth(req, response)
  File "C:\Python34\lib\urllib\request.py", line 571, in http_response
    'http', request, response, code, msg, hdrs)
  File "C:\Python34\lib\urllib\request.py", line 499, in error
    return self._call_chain(*args)
  File "C:\Python34\lib\urllib\request.py", line 433, in _call_chain
    result = func(*args)
  File "C:\Python34\lib\urllib\request.py", line 579, in http_error_default
    raise HTTPError(req.full_url, code, msg, hdrs, fp)
urllib.error.HTTPError: HTTP Error 404: Not Found
[EXCEPTION] [2015-02-18|10:40:19] >>>> Retrying request: http://128.2.211.183/wa/RemoteMonitor/dongleMontiorUpdate.php?update=TE9HO1JTU0k6IDEy
[EXCEPTION] [2015-02-18|10:40:19] >>>> Retrying request: http://128.2.211.183/wa/RemoteMonitor/dongleMontiorUpdate.php?update=TE9HOytDU1EgUmVzcG9uc2U6IEFUK0NTUQ0NCitDU1E6IDEyLDk5DQoNCk9LDQo=
[EXCEPTION] [2015-02-18|10:40:19] >>>> Retrying request: http://128.2.211.183/wa/RemoteMonitor/dongleMontiorUpdate.php?update=TE9HOytDUEFTIFJlc3BvbnNlOiBBVCtDUEFTDQ0KK0NQQVM6IDANCg0KT0sNCg==
[EXCEPTION] [2015-02-18|10:40:19] >>>> Retrying request: http://128.2.211.183/wa/RemoteMonitor/dongleMontiorUpdate.php?update=TE9HO0RFVklDRSBTVEFURTogUkVBRFk=
[EXCEPTION] [2015-02-18|10:40:19] URL Error... Timeout?
HTTP Error 404: Not Found
[EXCEPTION] [2015-02-18|10:40:19] URL Error... Timeout?
HTTP Error 404: Not Found
[EXCEPTION] [2015-02-18|10:40:19] >>>> Retrying request: http://128.2.211.183/wa/RemoteMonitor/dongleMontiorUpdate.php?update=TE9HO0RFVklDRSBTVEFURTogUkVBRFk=
[EXCEPTION] [2015-02-18|10:40:19] URL Error... Timeout?
HTTP Error 404: Not Found
[EXCEPTION] [2015-02-18|10:40:19] Traceback (most recent call last):
  File "C:\Users\PD\Documents\polly\pythonDongle\remote_monitor.py", line 15, in send_request
    wp = urllib2.urlopen(http_request, timeout=d.web_request_timeout)
  File "C:\Python34\lib\urllib\request.py", line 153, in urlopen
    return opener.open(url, data, timeout)
  File "C:\Python34\lib\urllib\request.py", line 461, in open
    response = meth(req, response)
  File "C:\Python34\lib\urllib\request.py", line 571, in http_response
    'http', request, response, code, msg, hdrs)
  File "C:\Python34\lib\urllib\request.py", line 499, in error
    return self._call_chain(*args)
  File "C:\Python34\lib\urllib\request.py", line 433, in _call_chain
    result = func(*args)
  File "C:\Python34\lib\urllib\request.py", line 579, in http_error_default
    raise HTTPError(req.full_url, code, msg, hdrs, fp)
urllib.error.HTTPError: HTTP Error 404: Not Found
[EXCEPTION] [2015-02-18|10:40:19] URL Error... Timeout?
HTTP Error 404: Not Found
[EXCEPTION] [2015-02-18|10:40:19] Traceback (most recent call last):
  File "C:\Users\PD\Documents\polly\pythonDongle\remote_monitor.py", line 15, in send_request
    wp = urllib2.urlopen(http_request, timeout=d.web_request_timeout)
  File "C:\Python34\lib\urllib\request.py", line 153, in urlopen
    return opener.open(url, data, timeout)
  File "C:\Python34\lib\urllib\request.py", line 461, in open
    response = meth(req, response)
  File "C:\Python34\lib\urllib\request.py", line 571, in http_response
    'http', request, response, code, msg, hdrs)
  File "C:\Python34\lib\urllib\request.py", line 499, in error
    return self._call_chain(*args)
  File "C:\Python34\lib\urllib\request.py", line 433, in _call_chain
    result = func(*args)
  File "C:\Python34\lib\urllib\request.py", line 579, in http_error_default
    raise HTTPError(req.full_url, code, msg, hdrs, fp)
urllib.error.HTTPError: HTTP Error 404: Not Found
[EXCEPTION] [2015-02-18|10:40:19] URL Error... Timeout?
HTTP Error 404: Not Found
[EXCEPTION] [2015-02-18|10:40:19] Traceback (most recent call last):
  File "C:\Users\PD\Documents\polly\pythonDongle\remote_monitor.py", line 15, in send_request
    wp = urllib2.urlopen(http_request, timeout=d.web_request_timeout)
  File "C:\Python34\lib\urllib\request.py", line 153, in urlopen
    return opener.open(url, data, timeout)
  File "C:\Python34\lib\urllib\request.py", line 461, in open
    response = meth(req, response)
  File "C:\Python34\lib\urllib\request.py", line 571, in http_response
    'http', request, response, code, msg, hdrs)
  File "C:\Python34\lib\urllib\request.py", line 499, in error
    return self._call_chain(*args)
  File "C:\Python34\lib\urllib\request.py", line 433, in _call_chain
    result = func(*args)
  File "C:\Python34\lib\urllib\request.py", line 579, in http_error_default
    raise HTTPError(req.full_url, code, msg, hdrs, fp)
urllib.error.HTTPError: HTTP Error 404: Not Found
[EXCEPTION] [2015-02-18|10:40:19] Traceback (most recent call last):
  File "C:\Users\PD\Documents\polly\pythonDongle\remote_monitor.py", line 15, in send_request
    wp = urllib2.urlopen(http_request, timeout=d.web_request_timeout)
  File "C:\Python34\lib\urllib\request.py", line 153, in urlopen
    return opener.open(url, data, timeout)
  File "C:\Python34\lib\urllib\request.py", line 461, in open
    response = meth(req, response)
  File "C:\Python34\lib\urllib\request.py", line 571, in http_response
    'http', request, response, code, msg, hdrs)
  File "C:\Python34\lib\urllib\request.py", line 499, in error
    return self._call_chain(*args)
  File "C:\Python34\lib\urllib\request.py", line 433, in _call_chain
    result = func(*args)
  File "C:\Python34\lib\urllib\request.py", line 579, in http_error_default
    raise HTTPError(req.full_url, code, msg, hdrs, fp)
urllib.error.HTTPError: HTTP Error 404: Not Found
[EXCEPTION] [2015-02-18|10:40:19] Traceback (most recent call last):
  File "C:\Users\PD\Documents\polly\pythonDongle\remote_monitor.py", line 15, in send_request
    wp = urllib2.urlopen(http_request, timeout=d.web_request_timeout)
  File "C:\Python34\lib\urllib\request.py", line 153, in urlopen
    return opener.open(url, data, timeout)
  File "C:\Python34\lib\urllib\request.py", line 461, in open
    response = meth(req, response)
  File "C:\Python34\lib\urllib\request.py", line 571, in http_response
    'http', request, response, code, msg, hdrs)
  File "C:\Python34\lib\urllib\request.py", line 499, in error
    return self._call_chain(*args)
  File "C:\Python34\lib\urllib\request.py", line 433, in _call_chain
    result = func(*args)
  File "C:\Python34\lib\urllib\request.py", line 579, in http_error_default
    raise HTTPError(req.full_url, code, msg, hdrs, fp)
urllib.error.HTTPError: HTTP Error 404: Not Found
[EXCEPTION] [2015-02-18|10:40:19] URL Error... Timeout?
HTTP Error 404: Not Found
[EXCEPTION] [2015-02-18|10:40:19] Traceback (most recent call last):
  File "C:\Users\PD\Documents\polly\pythonDongle\remote_monitor.py", line 15, in send_request
    wp = urllib2.urlopen(http_request, timeout=d.web_request_timeout)
  File "C:\Python34\lib\urllib\request.py", line 153, in urlopen
    return opener.open(url, data, timeout)
  File "C:\Python34\lib\urllib\request.py", line 461, in open
    response = meth(req, response)
  File "C:\Python34\lib\urllib\request.py", line 571, in http_response
    'http', request, response, code, msg, hdrs)
  File "C:\Python34\lib\urllib\request.py", line 499, in error
    return self._call_chain(*args)
  File "C:\Python34\lib\urllib\request.py", line 433, in _call_chain
    result = func(*args)
  File "C:\Python34\lib\urllib\request.py", line 579, in http_error_default
    raise HTTPError(req.full_url, code, msg, hdrs, fp)
urllib.error.HTTPError: HTTP Error 404: Not Found
[EXCEPTION] [2015-02-18|10:40:19] >>>> Retrying request: http://128.2.211.183/wa/RemoteMonitor/dongleMontiorUpdate.php?update=TE9HO0RFVklDRSBTVEFURTogUkVBRFk=
[EXCEPTION] [2015-02-18|10:40:19] >>>> Retrying request: http://128.2.211.183/wa/RemoteMonitor/dongleMontiorUpdate.php?update=TE9HOytDUEFTIFJlc3BvbnNlOiBBVCtDUEFTDQ0KK0NQQVM6IDANCg0KT0sNCg==
[EXCEPTION] [2015-02-18|10:40:19] URL Error... Timeout?
HTTP Error 404: Not Found
[EXCEPTION] [2015-02-18|10:40:19] >>>> Retrying request: http://128.2.211.183/wa/RemoteMonitor/dongleMontiorUpdate.php?update=TE9HOytDT1BTIFJlc3BvbnNlOiBBVCtDT1BTPw0NCitDT1BTOiAwLDAsIkNlbGxjb20gR04iLDINCg0KT0sNCg==
[EXCEPTION] [2015-02-18|10:40:19] URL Error... Timeout?
HTTP Error 404: Not Found
[EXCEPTION] [2015-02-18|10:40:19] Traceback (most recent call last):
  File "C:\Users\PD\Documents\polly\pythonDongle\remote_monitor.py", line 15, in send_request
    wp = urllib2.urlopen(http_request, timeout=d.web_request_timeout)
  File "C:\Python34\lib\urllib\request.py", line 153, in urlopen
    return opener.open(url, data, timeout)
  File "C:\Python34\lib\urllib\request.py", line 461, in open
    response = meth(req, response)
  File "C:\Python34\lib\urllib\request.py", line 571, in http_response
    'http', request, response, code, msg, hdrs)
  File "C:\Python34\lib\urllib\request.py", line 499, in error
    return self._call_chain(*args)
  File "C:\Python34\lib\urllib\request.py", line 433, in _call_chain
    result = func(*args)
  File "C:\Python34\lib\urllib\request.py", line 579, in http_error_default
    raise HTTPError(req.full_url, code, msg, hdrs, fp)
urllib.error.HTTPError: HTTP Error 404: Not Found
[EXCEPTION] [2015-02-18|10:40:19] URL Error... Timeout?
HTTP Error 404: Not Found
[EXCEPTION] [2015-02-18|10:40:19] Traceback (most recent call last):
  File "C:\Users\PD\Documents\polly\pythonDongle\remote_monitor.py", line 15, in send_request
    wp = urllib2.urlopen(http_request, timeout=d.web_request_timeout)
  File "C:\Python34\lib\urllib\request.py", line 153, in urlopen
    return opener.open(url, data, timeout)
  File "C:\Python34\lib\urllib\request.py", line 461, in open
    response = meth(req, response)
  File "C:\Python34\lib\urllib\request.py", line 571, in http_response
    'http', request, response, code, msg, hdrs)
  File "C:\Python34\lib\urllib\request.py", line 499, in error
    return self._call_chain(*args)
  File "C:\Python34\lib\urllib\request.py", line 433, in _call_chain
    result = func(*args)
  File "C:\Python34\lib\urllib\request.py", line 579, in http_error_default
    raise HTTPError(req.full_url, code, msg, hdrs, fp)
urllib.error.HTTPError: HTTP Error 404: Not Found
[EXCEPTION] [2015-02-18|10:40:19] Traceback (most recent call last):
  File "C:\Users\PD\Documents\polly\pythonDongle\remote_monitor.py", line 15, in send_request
    wp = urllib2.urlopen(http_request, timeout=d.web_request_timeout)
  File "C:\Python34\lib\urllib\request.py", line 153, in urlopen
    return opener.open(url, data, timeout)
  File "C:\Python34\lib\urllib\request.py", line 461, in open
    response = meth(req, response)
  File "C:\Python34\lib\urllib\request.py", line 571, in http_response
    'http', request, response, code, msg, hdrs)
  File "C:\Python34\lib\urllib\request.py", line 499, in error
    return self._call_chain(*args)
  File "C:\Python34\lib\urllib\request.py", line 433, in _call_chain
    result = func(*args)
  File "C:\Python34\lib\urllib\request.py", line 579, in http_error_default
    raise HTTPError(req.full_url, code, msg, hdrs, fp)
urllib.error.HTTPError: HTTP Error 404: Not Found
[EXCEPTION] [2015-02-18|10:40:19] >>>> Retrying request: http://128.2.211.183/wa/RemoteMonitor/dongleMontiorUpdate.php?update=TE9HOytDT1BTIFJlc3BvbnNlOiBBVCtDT1BTPw0NCitDT1BTOiAwLDAsIkNlbGxjb20gR04iLDINCg0KT0sNCg==
[EXCEPTION] [2015-02-18|10:40:20] URL Error... Timeout?
HTTP Error 404: Not Found
[EXCEPTION] [2015-02-18|10:40:20] URL Error... Timeout?
HTTP Error 404: Not Found
[EXCEPTION] [2015-02-18|10:40:20] URL Error... Timeout?
HTTP Error 404: Not Found
[EXCEPTION] [2015-02-18|10:40:20] >>>> Retrying request: http://128.2.211.183/wa/RemoteMonitor/dongleMontiorUpdate.php?update=QUxJVkU7WzIwMTUtMDItMTh8MTA6NDA6MTVdOzE7MTI7Q2VsbGNvbSBHTjtSRUFEWTtDT00xNw==
[EXCEPTION] [2015-02-18|10:40:20] Traceback (most recent call last):
  File "C:\Users\PD\Documents\polly\pythonDongle\remote_monitor.py", line 15, in send_request
    wp = urllib2.urlopen(http_request, timeout=d.web_request_timeout)
  File "C:\Python34\lib\urllib\request.py", line 153, in urlopen
    return opener.open(url, data, timeout)
  File "C:\Python34\lib\urllib\request.py", line 461, in open
    response = meth(req, response)
  File "C:\Python34\lib\urllib\request.py", line 571, in http_response
    'http', request, response, code, msg, hdrs)
  File "C:\Python34\lib\urllib\request.py", line 499, in error
    return self._call_chain(*args)
  File "C:\Python34\lib\urllib\request.py", line 433, in _call_chain
    result = func(*args)
  File "C:\Python34\lib\urllib\request.py", line 579, in http_error_default
    raise HTTPError(req.full_url, code, msg, hdrs, fp)
urllib.error.HTTPError: HTTP Error 404: Not Found
[EXCEPTION] [2015-02-18|10:40:20] Traceback (most recent call last):
  File "C:\Users\PD\Documents\polly\pythonDongle\remote_monitor.py", line 15, in send_request
    wp = urllib2.urlopen(http_request, timeout=d.web_request_timeout)
  File "C:\Python34\lib\urllib\request.py", line 153, in urlopen
    return opener.open(url, data, timeout)
  File "C:\Python34\lib\urllib\request.py", line 461, in open
    response = meth(req, response)
  File "C:\Python34\lib\urllib\request.py", line 571, in http_response
    'http', request, response, code, msg, hdrs)
  File "C:\Python34\lib\urllib\request.py", line 499, in error
    return self._call_chain(*args)
  File "C:\Python34\lib\urllib\request.py", line 433, in _call_chain
    result = func(*args)
  File "C:\Python34\lib\urllib\request.py", line 579, in http_error_default
    raise HTTPError(req.full_url, code, msg, hdrs, fp)
urllib.error.HTTPError: HTTP Error 404: Not Found
[EXCEPTION] [2015-02-18|10:40:20] URL Error... Timeout?
HTTP Error 404: Not Found
[EXCEPTION] [2015-02-18|10:40:20] >>>> Retrying request: http://128.2.211.183/wa/RemoteMonitor/dongleMontiorUpdate.php?update=TE9HOytDU1EgUmVzcG9uc2U6IEFUK0NTUQ0NCitDU1E6IDEyLDk5DQoNCk9LDQo=
[EXCEPTION] [2015-02-18|10:40:20] URL Error... Timeout?
HTTP Error 404: Not Found
[EXCEPTION] [2015-02-18|10:40:20] Traceback (most recent call last):
  File "C:\Users\PD\Documents\polly\pythonDongle\remote_monitor.py", line 15, in send_request
    wp = urllib2.urlopen(http_request, timeout=d.web_request_timeout)
  File "C:\Python34\lib\urllib\request.py", line 153, in urlopen
    return opener.open(url, data, timeout)
  File "C:\Python34\lib\urllib\request.py", line 461, in open
    response = meth(req, response)
  File "C:\Python34\lib\urllib\request.py", line 571, in http_response
    'http', request, response, code, msg, hdrs)
  File "C:\Python34\lib\urllib\request.py", line 499, in error
    return self._call_chain(*args)
  File "C:\Python34\lib\urllib\request.py", line 433, in _call_chain
    result = func(*args)
  File "C:\Python34\lib\urllib\request.py", line 579, in http_error_default
    raise HTTPError(req.full_url, code, msg, hdrs, fp)
urllib.error.HTTPError: HTTP Error 404: Not Found
[EXCEPTION] [2015-02-18|10:40:20] Traceback (most recent call last):
  File "C:\Users\PD\Documents\polly\pythonDongle\remote_monitor.py", line 15, in send_request
    wp = urllib2.urlopen(http_request, timeout=d.web_request_timeout)
  File "C:\Python34\lib\urllib\request.py", line 153, in urlopen
    return opener.open(url, data, timeout)
  File "C:\Python34\lib\urllib\request.py", line 461, in open
    response = meth(req, response)
  File "C:\Python34\lib\urllib\request.py", line 571, in http_response
    'http', request, response, code, msg, hdrs)
  File "C:\Python34\lib\urllib\request.py", line 499, in error
    return self._call_chain(*args)
  File "C:\Python34\lib\urllib\request.py", line 433, in _call_chain
    result = func(*args)
  File "C:\Python34\lib\urllib\request.py", line 579, in http_error_default
    raise HTTPError(req.full_url, code, msg, hdrs, fp)
urllib.error.HTTPError: HTTP Error 404: Not Found
[EXCEPTION] [2015-02-18|10:40:20] >>>> Retrying request: http://128.2.211.183/wa/RemoteMonitor/dongleMontiorUpdate.php?update=TE9HOytDUEFTIFJlc3BvbnNlOiBBVCtDUEFTDQ0KK0NQQVM6IDANCg0KT0sNCg==
[EXCEPTION] [2015-02-18|10:40:20] >>>> Retrying request: http://128.2.211.183/wa/RemoteMonitor/dongleMontiorUpdate.php?update=TE9HOytDUEFTIFJlc3BvbnNlOiBBVCtDUEFTDQ0KK0NQQVM6IDANCg0KT0sNCg==
tp_request, timeout=d.web_request_timeout)
  File "C:\Python34\lib\urllib\request.py", line 153, in urlopen
    return opener.open(url, data, timeout)
  File "C:\Python34\lib\urllib\request.py", line 461, in open
    response = meth(req, response)
  File "C:\Python34\lib\urllib\request.py", line 571, in http_response
    'http', request, response, code, msg, hdrs)
  File "C:\Python34\lib\urllib\request.py", line 499, in error
    return self._call_chain(*args)
  File "C:\Python34\lib\urllib\request.py", line 433, in _call_chain
    result = func(*args)
  File "C:\Python34\lib\urllib\request.py", line 579, in http_error_default
    raise HTTPError(req.full_url, code, msg, hdrs, fp)
urllib.error.HTTPError: HTTP Error 404: Not Found
[EXCEPTION] [2015-02-18|10:40:20] >>>> Retrying request: http://128.2.211.183/wa/RemoteMonitor/dongleMontiorUpdate.php?update=TE9HOytDUEFTIFJlc3BvbnNlOiBBVCtDUEFTDQ0KK0NQQVM6IDANCg0KT0sNCg==
[EXCEPTION] [2015-02-18|10:40:20] URL Error... Timeout?
HTTP Error 404: Not Found
[EXCEPTION] [2015-02-18|10:40:20] >>>> Retrying request: http://128.2.211.183/wa/RemoteMonitor/dongleMontiorUpdate.php?update=QUxJVkU7WzIwMTUtMDItMTh8MTA6NDA6MTVdOzE7MTI7Q2VsbGNvbSBHTjtSRUFEWTtDT00xNw==
[EXCEPTION] [2015-02-18|10:40:20] >>>> Retrying request: http://128.2.211.183/wa/RemoteMonitor/dongleMontiorUpdate.php?update=TE9HOytDUEFTIFJlc3BvbnNlOiBBVCtDUEFTDQ0KK0NQQVM6IDANCg0KT0sNCg==
[EXCEPTION] [2015-02-18|10:40:20] URL Error... Timeout?
HTTP Error 404: Not Found
[EXCEPTION] [2015-02-18|10:40:20] Traceback (most recent call last):
  File "C:\Users\PD\Documents\polly\pythonDongle\remote_monitor.py", line 15, in send_request
    wp = urllib2.urlopen(http_request, timeout=d.web_request_timeout)
  File "C:\Python34\lib\urllib\request.py", line 153, in urlopen
    return opener.open(url, data, timeout)
  File "C:\Python34\lib\urllib\request.py", line 461, in open
    response = meth(req, response)
  File "C:\Python34\lib\urllib\request.py", line 571, in http_response
    'http', request, response, code, msg, hdrs)
  File "C:\Python34\lib\urllib\request.py", line 499, in error
    return self._call_chain(*args)
  File "C:\Python34\lib\urllib\request.py", line 433, in _call_chain
    result = func(*args)
  File "C:\Python34\lib\urllib\request.py", line 579, in http_error_default
    raise HTTPError(req.full_url, code, msg, hdrs, fp)
urllib.error.HTTPError: HTTP Error 404: Not Found
[EXCEPTION] [2015-02-18|10:40:20] Traceback (most recent call last):
  File "C:\Users\PD\Documents\polly\pythonDongle\remote_monitor.py", line 15, in send_request
    wp = urllib2.urlopen(http_request, timeout=d.web_request_timeout)
  File "C:\Python34\lib\urllib\request.py", line 153, in urlopen
    return opener.open(url, data, timeout)
  File "C:\Python34\lib\urllib\request.py", line 461, in open
    response = meth(req, response)
  File "C:\Python34\lib\urllib\request.py", line 571, in http_response
    'http', request, response, code, msg, hdrs)
  File "C:\Python34\lib\urllib\request.py", line 499, in error
    return self._call_chain(*args)
  File "C:\Python34\lib\urllib\request.py", line 433, in _call_chain
    result = func(*args)
  File "C:\Python34\lib\urllib\request.py", line 579, in http_error_default
    raise HTTPError(req.full_url, code, msg, hdrs, fp)
urllib.error.HTTPError: HTTP Error 404: Not Found
[EXCEPTION] [2015-02-18|10:40:20] URL Error... Timeout?
HTTP Error 404: Not Found
[EXCEPTION] [2015-02-18|10:40:20] URL Error... Timeout?
HTTP Error 404: Not Found
[EXCEPTION] [2015-02-18|10:40:20] URL Error... Timeout?
HTTP Error 404: Not Found
[EXCEPTION] [2015-02-18|10:40:20] URL Error... Timeout?
HTTP Error 404: Not Found
[EXCEPTION] [2015-02-18|10:40:20] URL Error... Timeout?
HTTP Error 404: Not Found
[EXCEPTION] [2015-02-18|10:40:20] URL Error... Timeout?
HTTP Error 404: Not Found
[EXCEPTION] [2015-02-18|10:40:20] URL Error... Timeout?
HTTP Error 404: Not Found
[EXCEPTION] [2015-02-18|10:40:20] URL Error... Timeout?
HTTP Error 404: Not Found
[EXCEPTION] [2015-02-18|10:40:20] URL Error... Timeout?
HTTP Error 404: Not Found
[EXCEPTION] [2015-02-18|10:40:21] Traceback (most recent call last):
  File "C:\Users\PD\Documents\polly\pythonDongle\remote_monitor.py", line 15, in send_request
    wp = urllib2.urlopen(http_request, timeout=d.web_request_timeout)
  File "C:\Python34\lib\urllib\request.py", line 153, in urlopen
    return opener.open(url, data, timeout)
  File "C:\Python34\lib\urllib\request.py", line 461, in open
    response = meth(req, response)
  File "C:\Python34\lib\urllib\request.py", line 571, in http_response
    'http', request, response, code, msg, hdrs)
  File "C:\Python34\lib\urllib\request.py", line 499, in error
    return self._call_chain(*args)
  File "C:\Python34\lib\urllib\request.py", line 433, in _call_chain
    result = func(*args)
  File "C:\Python34\lib\urllib\request.py", line 579, in http_error_default
    raise HTTPError(req.full_url, code, msg, hdrs, fp)
urllib.error.HTTPError: HTTP Error 404: Not Found
[EXCEPTION] [2015-02-18|10:40:21] Traceback (most recent call last):
  File "C:\Users\PD\Documents\polly\pythonDongle\remote_monitor.py", line 15, in send_request
    wp = urllib2.urlopen(http_request, timeout=d.web_request_timeout)
  File "C:\Python34\lib\urllib\request.py", line 153, in urlopen
    return opener.open(url, data, timeout)
  File "C:\Python34\lib\urllib\request.py", line 461, in open
    response = meth(req, response)
  File "C:\Python34\lib\urllib\request.py", line 571, in http_response
    'http', request, response, code, msg, hdrs)
  File "C:\Python34\lib\urllib\request.py", line 499, in error
    return self._call_chain(*args)
  File "C:\Python34\lib\urllib\request.py", line 433, in _call_chain
    result = func(*args)
  File "C:\Python34\lib\urllib\request.py", line 579, in http_error_default
    raise HTTPError(req.full_url, code, msg, hdrs, fp)
urllib.error.HTTPError: HTTP Error 404: Not Found
[EXCEPTION] [2015-02-18|10:40:21] Traceback (most recent call last):
  File "C:\Users\PD\Documents\polly\pythonDongle\remote_monitor.py", line 15, in send_request
    wp = urllib2.urlopen(http_request, timeout=d.web_request_timeout)
  File "C:\Python34\lib\urllib\request.py", line 153, in urlopen
    return opener.open(url, data, timeout)
  File "C:\Python34\lib\urllib\request.py", line 461, in open
    response = meth(req, response)
  File "C:\Python34\lib\urllib\request.py", line 571, in http_response
    'http', request, response, code, msg, hdrs)
  File "C:\Python34\lib\urllib\request.py", line 499, in error
    return self._call_chain(*args)
  File "C:\Python34\lib\urllib\request.py", line 433, in _call_chain
    result = func(*args)
  File "C:\Python34\lib\urllib\request.py", line 579, in http_error_default
    raise HTTPError(req.full_url, code, msg, hdrs, fp)
urllib.error.HTTPError: HTTP Error 404: Not Found
[EXCEPTION] [2015-02-18|10:40:21] Traceback (most recent call last):
  File "C:\Users\PD\Documents\polly\pythonDongle\remote_monitor.py", line 15, in send_request
    wp = urllib2.urlopen(http_request, timeout=d.web_request_timeout)
  File "C:\Python34\lib\urllib\request.py", line 153, in urlopen
    return opener.open(url, data, timeout)
  File "C:\Python34\lib\urllib\request.py", line 461, in open
    response = meth(req, response)
  File "C:\Python34\lib\urllib\request.py", line 571, in http_response
    'http', request, response, code, msg, hdrs)
  File "C:\Python34\lib\urllib\request.py", line 499, in error
    return self._call_chain(*args)
  File "C:\Python34\lib\urllib\request.py", line 433, in _call_chain
    result = func(*args)
  File "C:\Python34\lib\urllib\request.py", line 579, in http_error_default
    raise HTTPError(req.full_url, code, msg, hdrs, fp)
urllib.error.HTTPError: HTTP Error 404: Not Found
[EXCEPTION] [2015-02-18|10:40:21] Traceback (most recent call last):
  File "C:\Users\PD\Documents\polly\pythonDongle\remote_monitor.py", line 15, in send_request
    wp = urllib2.urlopen(http_request, timeout=d.web_request_timeout)
  File "C:\Python34\lib\urllib\request.py", line 153, in urlopen
    return opener.open(url, data, timeout)
  File "C:\Python34\lib\urllib\request.py", line 461, in open
    response = meth(req, response)
  File "C:\Python34\lib\urllib\request.py", line 571, in http_response
    'http', request, response, code, msg, hdrs)
  File "C:\Python34\lib\urllib\request.py", line 499, in error
    return self._call_chain(*args)
  File "C:\Python34\lib\urllib\request.py", line 433, in _call_chain
    result = func(*args)
  File "C:\Python34\lib\urllib\request.py", line 579, in http_error_default
    raise HTTPError(req.full_url, code, msg, hdrs, fp)
urllib.error.HTTPError: HTTP Error 404: Not Found
[EXCEPTION] [2015-02-18|10:40:21] Traceback (most recent call last):
  File "C:\Users\PD\Documents\polly\pythonDongle\remote_monitor.py", line 15, in send_request
    wp = urllib2.urlopen(http_request, timeout=d.web_request_timeout)
  File "C:\Python34\lib\urllib\request.py", line 153, in urlopen
    return opener.open(url, data, timeout)
  File "C:\Python34\lib\urllib\request.py", line 461, in open
    response = meth(req, response)
  File "C:\Python34\lib\urllib\request.py", line 571, in http_response
    'http', request, response, code, msg, hdrs)
  File "C:\Python34\lib\urllib\request.py", line 499, in error
    return self._call_chain(*args)
  File "C:\Python34\lib\urllib\request.py", line 433, in _call_chain
    result = func(*args)
  File "C:\Python34\lib\urllib\request.py", line 579, in http_error_default
    raise HTTPError(req.full_url, code, msg, hdrs, fp)
urllib.error.HTTPError: HTTP Error 404: Not Found
[EXCEPTION] [2015-02-18|10:40:21] >>>> Retrying request: http://128.2.211.183/wa/RemoteMonitor/dongleMontiorUpdate.php?update=TE9HO1JTU0k6IDEy
[EXCEPTION] [2015-02-18|10:40:21] Traceback (most recent call last):
  File "C:\Users\PD\Documents\polly\pythonDongle\remote_monitor.py", line 15, in send_request
    wp = urllib2.urlopen(http_request, timeout=d.web_request_timeout)
  File "C:\Python34\lib\urllib\request.py", line 153, in urlopen
    return opener.open(url, data, timeout)
  File "C:\Python34\lib\urllib\request.py", line 461, in open
    response = meth(req, response)
  File "C:\Python34\lib\urllib\request.py", line 571, in http_response
    'http', request, response, code, msg, hdrs)
  File "C:\Python34\lib\urllib\request.py", line 499, in error
    return self._call_chain(*args)
  File "C:\Python34\lib\urllib\request.py", line 433, in _call_chain
    result = func(*args)
  File "C:\Python34\lib\urllib\request.py", line 579, in http_error_default
    raise HTTPError(req.full_url, code, msg, hdrs, fp)
urllib.error.HTTPError: HTTP Error 404: Not Found
[EXCEPTION] [2015-02-18|10:40:21] Traceback (most recent call last):
  File "C:\Users\PD\Documents\polly\pythonDongle\remote_monitor.py", line 15, in send_request
    wp = urllib2.urlopen(http_request, timeout=d.web_request_timeout)
  File "C:\Python34\lib\urllib\request.py", line 153, in urlopen
    return opener.open(url, data, timeout)
  File "C:\Python34\lib\urllib\request.py", line 461, in open
    response = meth(req, response)
  File "C:\Python34\lib\urllib\request.py", line 571, in http_response
    'http', request, response, code, msg, hdrs)
  File "C:\Python34\lib\urllib\request.py", line 499, in error
    return self._call_chain(*args)
  File "C:\Python34\lib\urllib\request.py", line 433, in _call_chain
    result = func(*args)
  File "C:\Python34\lib\urllib\request.py", line 579, in http_error_default
    raise HTTPError(req.full_url, code, msg, hdrs, fp)
urllib.error.HTTPError: HTTP Error 404: Not Found
[EXCEPTION] [2015-02-18|10:40:21] Traceback (most recent call last):
  File "C:\Users\PD\Documents\polly\pythonDongle\remote_monitor.py", line 15, in send_request
    wp = urllib2.urlopen(http_request, timeout=d.web_request_timeout)
  File "C:\Python34\lib\urllib\request.py", line 153, in urlopen
    return opener.open(url, data, timeout)
  File "C:\Python34\lib\urllib\request.py", line 461, in open
    response = meth(req, response)
  File "C:\Python34\lib\urllib\request.py", line 571, in http_response
    'http', request, response, code, msg, hdrs)
  File "C:\Python34\lib\urllib\request.py", line 499, in error
    return self._call_chain(*args)
  File "C:\Python34\lib\urllib\request.py", line 433, in _call_chain
    result = func(*args)
  File "C:\Python34\lib\urllib\request.py", line 579, in http_error_default
    raise HTTPError(req.full_url, code, msg, hdrs, fp)
urllib.error.HTTPError: HTTP Error 404: Not Found
[EXCEPTION] [2015-02-18|10:40:21] Traceback (most recent call last):
  File "C:\Users\PD\Documents\polly\pythonDongle\remote_monitor.py", line 15, in send_request
    wp = urllib2.urlopen(http_request, timeout=d.web_request_timeout)
  File "C:\Python34\lib\urllib\request.py", line 153, in urlopen
    return opener.open(url, data, timeout)
  File "C:\Python34\lib\urllib\request.py", line 461, in open
    response = meth(req, response)
  File "C:\Python34\lib\urllib\request.py", line 571, in http_response
    'http', request, response, code, msg, hdrs)
  File "C:\Python34\lib\urllib\request.py", line 499, in error
    return self._call_chain(*args)
  File "C:\Python34\lib\urllib\request.py", line 433, in _call_chain
    result = func(*args)
  File "C:\Python34\lib\urllib\request.py", line 579, in http_error_default
    raise HTTPError(req.full_url, code, msg, hdrs, fp)
urllib.error.HTTPError: HTTP Error 404: Not Found
[EXCEPTION] [2015-02-18|10:40:21] >>>> Retrying request: http://128.2.211.183/wa/RemoteMonitor/dongleMontiorUpdate.php?update=TE9HO0NBUlJJRVI6IENlbGxjb20gR04=
[EXCEPTION] [2015-02-18|10:40:21] URL Error... Timeout?
HTTP Error 404: Not Found
[EXCEPTION] [2015-02-18|10:40:21] Traceback (most recent call last):
  File "C:\Users\PD\Documents\polly\pythonDongle\remote_monitor.py", line 15, in send_request
    wp = urllib2.urlopen(http_request, timeout=d.web_request_timeout)
  File "C:\Python34\lib\urllib\request.py", line 153, in urlopen
    return opener.open(url, data, timeout)
  File "C:\Python34\lib\urllib\request.py", line 461, in open
    response = meth(req, response)
  File "C:\Python34\lib\urllib\request.py", line 571, in http_response
    'http', request, response, code, msg, hdrs)
  File "C:\Python34\lib\urllib\request.py", line 499, in error
    return self._call_chain(*args)
  File "C:\Python34\lib\urllib\request.py", line 433, in _call_chain
    result = func(*args)
  File "C:\Python34\lib\urllib\request.py", line 579, in http_error_default
    raise HTTPError(req.full_url, code, msg, hdrs, fp)
urllib.error.HTTPError: HTTP Error 404: Not Found
[EXCEPTION] [2015-02-18|10:40:21] >>>> Retrying request: http://128.2.211.183/wa/RemoteMonitor/dongleMontiorUpdate.php?update=TE9HO0RFVklDRSBTVEFURTogUkVBRFk=
[EXCEPTION] [2015-02-18|10:40:21] >>>> Retrying request: http://128.2.211.183/wa/RemoteMonitor/dongleMontiorUpdate.php?update=TE9HO0RFVklDRSBTVEFURTogUkVBRFk=
[EXCEPTION] [2015-02-18|10:40:21] >>>> Retrying request: http://128.2.211.183/wa/RemoteMonitor/dongleMontiorUpdate.php?update=TE9HO0NBUlJJRVI6IENlbGxjb20gR04=
[EXCEPTION] [2015-02-18|10:40:21] URL Error... Timeout?
HTTP Error 404: Not Found
[EXCEPTION] [2015-02-18|10:40:21] >>>> Retrying request: http://128.2.211.183/wa/RemoteMonitor/dongleMontiorUpdate.php?update=TE9HO0RFVklDRSBTVEFURTogUkVBRFk=
[EXCEPTION] [2015-02-18|10:40:21] >>>> Retrying request: http://128.2.211.183/wa/RemoteMonitor/dongleMontiorUpdate.php?update=TE9HO0RFVklDRSBTVEFURTogUkVBRFk=
[EXCEPTION] [2015-02-18|10:40:21] >>>> Retrying request: http://128.2.211.183/wa/RemoteMonitor/dongleMontiorUpdate.php?update=TE9HO0RFVklDRSBTVEFURTogUkVBRFk=
[EXCEPTION] [2015-02-18|10:40:21] URL Error... Timeout?
HTTP Error 404: Not Found
[EXCEPTION] [2015-02-18|10:40:21] Traceback (most recent call last):
  File "C:\Users\PD\Documents\polly\pythonDongle\remote_monitor.py", line 15, in send_request
    wp = urllib2.urlopen(http_request, timeout=d.web_request_timeout)
  File "C:\Python34\lib\urllib\request.py", line 153, in urlopen
    return opener.open(url, data, timeout)
  File "C:\Python34\lib\urllib\request.py", line 461, in open
    response = meth(req, response)
  File "C:\Python34\lib\urllib\request.py", line 571, in http_response
    'http', request, response, code, msg, hdrs)
  File "C:\Python34\lib\urllib\request.py", line 499, in error
    return self._call_chain(*args)
  File "C:\Python34\lib\urllib\request.py", line 433, in _call_chain
    result = func(*args)
  File "C:\Python34\lib\urllib\request.py", line 579, in http_error_default
    raise HTTPError(req.full_url, code, msg, hdrs, fp)
urllib.error.HTTPError: HTTP Error 404: Not Found
[EXCEPTION] [2015-02-18|10:40:21] URL Error... Timeout?
HTTP Error 404: Not Found
[EXCEPTION] [2015-02-18|10:40:21] Traceback (most recent call last):
  File "C:\Users\PD\Documents\polly\pythonDongle\remote_monitor.py", line 15, in send_request
    wp = urllib2.urlopen(http_request, timeout=d.web_request_timeout)
  File "C:\Python34\lib\urllib\request.py", line 153, in urlopen
    return opener.open(url, data, timeout)
  File "C:\Python34\lib\urllib\request.py", line 461, in open
    response = meth(req, response)
  File "C:\Python34\lib\urllib\request.py", line 571, in http_response
    'http', request, response, code, msg, hdrs)
  File "C:\Python34\lib\urllib\request.py", line 499, in error
    return self._call_chain(*args)
  File "C:\Python34\lib\urllib\request.py", line 433, in _call_chain
    result = func(*args)
  File "C:\Python34\lib\urllib\request.py", line 579, in http_error_default
    raise HTTPError(req.full_url, code, msg, hdrs, fp)
urllib.error.HTTPError: HTTP Error 404: Not Found
[EXCEPTION] [2015-02-18|10:40:21] URL Error... Timeout?
HTTP Error 404: Not Found
[EXCEPTION] [2015-02-18|10:40:21] URL Error... Timeout?
HTTP Error 404: Not Found
[EXCEPTION] [2015-02-18|10:40:21] URL Error... Timeout?
HTTP Error 404: Not Found
[EXCEPTION] [2015-02-18|10:40:21] URL Error... Timeout?
HTTP Error 404: Not Found
[EXCEPTION] [2015-02-18|10:40:21] >>>> Retrying request: http://128.2.211.183/wa/RemoteMonitor/dongleMontiorUpdate.php?update=QUxJVkU7WzIwMTUtMDItMTh8MTA6NDA6MTVdOzE7MTI7Q2VsbGNvbSBHTjtSRUFEWTtDT00yMg==
[EXCEPTION] [2015-02-18|10:40:21] >>>> Retrying request: http://128.2.211.183/wa/RemoteMonitor/dongleMontiorUpdate.php?update=TE9HO0NBUlJJRVI6IENlbGxjb20gR04=
[EXCEPTION] [2015-02-18|10:40:21] >>>> Retrying request: http://128.2.211.183/wa/RemoteMonitor/dongleMontiorUpdate.php?update=TE9HOytDU1EgUmVzcG9uc2U6IEFUK0NTUQ0NCitDU1E6IDEyLDk5DQoNCk9LDQo=
[EXCEPTION] [2015-02-18|10:40:21] URL Error... Timeout?
HTTP Error 404: Not Found
[EXCEPTION] [2015-02-18|10:40:21] Traceback (most recent call last):
  File "C:\Users\PD\Documents\polly\pythonDongle\remote_monitor.py", line 15, in send_request
    wp = urllib2.urlopen(http_request, timeout=d.web_request_timeout)
  File "C:\Python34\lib\urllib\request.py", line 153, in urlopen
    return opener.open(url, data, timeout)
  File "C:\Python34\lib\urllib\request.py", line 461, in open
    response = meth(req, response)
  File "C:\Python34\lib\urllib\request.py", line 571, in http_response
    'http', request, response, code, msg, hdrs)
  File "C:\Python34\lib\urllib\request.py", line 499, in error
    return self._call_chain(*args)
  File "C:\Python34\lib\urllib\request.py", line 433, in _call_chain
    result = func(*args)
  File "C:\Python34\lib\urllib\request.py", line 579, in http_error_default
    raise HTTPError(req.full_url, code, msg, hdrs, fp)
urllib.error.HTTPError: HTTP Error 404: Not Found
[EXCEPTION] [2015-02-18|10:40:21] Traceback (most recent call last):
  File "C:\Users\PD\Documents\polly\pythonDongle\remote_monitor.py", line 15, in send_request
    wp = urllib2.urlopen(http_request, timeout=d.web_request_timeout)
  File "C:\Python34\lib\urllib\request.py", line 153, in urlopen
    return opener.open(url, data, timeout)
  File "C:\Python34\lib\urllib\request.py", line 461, in open
    response = meth(req, response)
  File "C:\Python34\lib\urllib\request.py", line 571, in http_response
    'http', request, response, code, msg, hdrs)
  File "C:\Python34\lib\urllib\request.py", line 499, in error
    return self._call_chain(*args)
  File "C:\Python34\lib\urllib\request.py", line 433, in _call_chain
    result = func(*args)
  File "C:\Python34\lib\urllib\request.py", line 579, in http_error_default
    raise HTTPError(req.full_url, code, msg, hdrs, fp)
urllib.error.HTTPError: HTTP Error 404: Not Found
[EXCEPTION] [2015-02-18|10:40:21] Traceback (most recent call last):
  File "C:\Users\PD\Documents\polly\pythonDongle\remote_monitor.py", line 15, in send_request
    wp = urllib2.urlopen(http_request, timeout=d.web_request_timeout)
  File "C:\Python34\lib\urllib\request.py", line 153, in urlopen
    return opener.open(url, data, timeout)
  File "C:\Python34\lib\urllib\request.py", line 461, in open
    response = meth(req, response)
  File "C:\Python34\lib\urllib\request.py", line 571, in http_response
    'http', request, response, code, msg, hdrs)
  File "C:\Python34\lib\urllib\request.py", line 499, in error
    return self._call_chain(*args)
  File "C:\Python34\lib\urllib\request.py", line 433, in _call_chain
    result = func(*args)
  File "C:\Python34\lib\urllib\request.py", line 579, in http_error_default
    raise HTTPError(req.full_url, code, msg, hdrs, fp)
urllib.error.HTTPError: HTTP Error 404: Not Found
[EXCEPTION] [2015-02-18|10:40:21] Traceback (most recent call last):
  File "C:\Users\PD\Documents\polly\pythonDongle\remote_monitor.py", line 15, in send_request
    wp = urllib2.urlopen(http_request, timeout=d.web_request_timeout)
  File "C:\Python34\lib\urllib\request.py", line 153, in urlopen
    return opener.open(url, data, timeout)
  File "C:\Python34\lib\urllib\request.py", line 461, in open
    response = meth(req, response)
  File "C:\Python34\lib\urllib\request.py", line 571, in http_response
    'http', request, response, code, msg, hdrs)
  File "C:\Python34\lib\urllib\request.py", line 499, in error
    return self._call_chain(*args)
  File "C:\Python34\lib\urllib\request.py", line 433, in _call_chain
    result = func(*args)
  File "C:\Python34\lib\urllib\request.py", line 579, in http_error_default
    raise HTTPError(req.full_url, code, msg, hdrs, fp)
urllib.error.HTTPError: HTTP Error 404: Not Found
[EXCEPTION] [2015-02-18|10:40:21] URL Error... Timeout?
HTTP Error 404: Not Found
[EXCEPTION] [2015-02-18|10:40:21] URL Error... Timeout?
HTTP Error 404: Not Found
[EXCEPTION] [2015-02-18|10:40:21] Traceback (most recent call last):
  File "C:\Users\PD\Documents\polly\pythonDongle\remote_monitor.py", line 15, in send_request
    wp = urllib2.urlopen(http_request, timeout=d.web_request_timeout)
  File "C:\Python34\lib\urllib\request.py", line 153, in urlopen
    return opener.open(url, data, timeout)
  File "C:\Python34\lib\urllib\request.py", line 461, in open
    response = meth(req, response)
  File "C:\Python34\lib\urllib\request.py", line 571, in http_response
    'http', request, response, code, msg, hdrs)
  File "C:\Python34\lib\urllib\request.py", line 499, in error
    return self._call_chain(*args)
  File "C:\Python34\lib\urllib\request.py", line 433, in _call_chain
    result = func(*args)
  File "C:\Python34\lib\urllib\request.py", line 579, in http_error_default
    raise HTTPError(req.full_url, code, msg, hdrs, fp)
urllib.error.HTTPError: HTTP Error 404: Not Found
[EXCEPTION] [2015-02-18|10:40:21] >>>> Retrying request: http://128.2.211.183/wa/RemoteMonitor/dongleMontiorUpdate.php?update=TE9HOytDU1EgUmVzcG9uc2U6IEFUK0NTUQ0NCitDU1E6IDEyLDk5DQoNCk9LDQo=
[EXCEPTION] [2015-02-18|10:40:21] >>>> Retrying request: http://128.2.211.183/wa/RemoteMonitor/dongleMontiorUpdate.php?update=TE9HOytDU1EgUmVzcG9uc2U6IEFUK0NTUQ0NCitDU1E6IDEyLDk5DQoNCk9LDQo=
[EXCEPTION] [2015-02-18|10:40:21] >>>> Retrying request: http://128.2.211.183/wa/RemoteMonitor/dongleMontiorUpdate.php?update=TE9HOytDU1EgUmVzcG9uc2U6IEFUK0NTUQ0NCitDU1E6IDEyLDk5DQoNCk9LDQo=
[EXCEPTION] [2015-02-18|10:40:21] >>>> Retrying request: http://128.2.211.183/wa/RemoteMonitor/dongleMontiorUpdate.php?update=TE9HOytDU1EgUmVzcG9uc2U6IEFUK0NTUQ0NCitDU1E6IDEyLDk5DQoNCk9LDQo=
[EXCEPTION] [2015-02-18|10:40:21] Traceback (most recent call last):
  File "C:\Users\PD\Documents\polly\pythonDongle\remote_monitor.py", line 15, in send_request
    wp = urllib2.urlopen(http_request, timeout=d.web_request_timeout)
  File "C:\Python34\lib\urllib\request.py", line 153, in urlopen
    return opener.open(url, data, timeout)
  File "C:\Python34\lib\urllib\request.py", line 461, in open
    response = meth(req, response)
  File "C:\Python34\lib\urllib\request.py", line 571, in http_response
    'http', request, response, code, msg, hdrs)
  File "C:\Python34\lib\urllib\request.py", line 499, in error
    return self._call_chain(*args)
  File "C:\Python34\lib\urllib\request.py", line 433, in _call_chain
    result = func(*args)
  File "C:\Python34\lib\urllib\request.py", line 579, in http_error_default
    raise HTTPError(req.full_url, code, msg, hdrs, fp)
urllib.error.HTTPError: HTTP Error 404: Not Found
[EXCEPTION] [2015-02-18|10:40:21] URL Error... Timeout?
HTTP Error 404: Not Found
[EXCEPTION] [2015-02-18|10:40:21] URL Error... Timeout?
HTTP Error 404: Not Found
[EXCEPTION] [2015-02-18|10:40:21] URL Error... Timeout?
HTTP Error 404: Not Found
[EXCEPTION] [2015-02-18|10:40:21] URL Error... Timeout?
HTTP Error 404: Not Found
[EXCEPTION] [2015-02-18|10:40:21] >>>> Retrying request: http://128.2.211.183/wa/RemoteMonitor/dongleMontiorUpdate.php?update=TE9HO1tDT00xNl0gWzIwMTUtMDItMTh8MTA6NDA6MThdIFNlbmRpbmcga2VlcC1hbGl2ZSBtZXNzYWdlIHRvIHNlcnZlci4uLg==
[EXCEPTION] [2015-02-18|10:40:21] Traceback (most recent call last):
  File "C:\Users\PD\Documents\polly\pythonDongle\remote_monitor.py", line 15, in send_request
    wp = urllib2.urlopen(http_request, timeout=d.web_request_timeout)
  File "C:\Python34\lib\urllib\request.py", line 153, in urlopen
    return opener.open(url, data, timeout)
  File "C:\Python34\lib\urllib\request.py", line 461, in open
    response = meth(req, response)
  File "C:\Python34\lib\urllib\request.py", line 571, in http_response
    'http', request, response, code, msg, hdrs)
  File "C:\Python34\lib\urllib\request.py", line 499, in error
    return self._call_chain(*args)
  File "C:\Python34\lib\urllib\request.py", line 433, in _call_chain
    result = func(*args)
  File "C:\Python34\lib\urllib\request.py", line 579, in http_error_default
    raise HTTPError(req.full_url, code, msg, hdrs, fp)
urllib.error.HTTPError: HTTP Error 404: Not Found
[EXCEPTION] [2015-02-18|10:40:21] Traceback (most recent call last):
  File "C:\Users\PD\Documents\polly\pythonDongle\remote_monitor.py", line 15, in send_request
    wp = urllib2.urlopen(http_request, timeout=d.web_request_timeout)
  File "C:\Python34\lib\urllib\request.py", line 153, in urlopen
    return opener.open(url, data, timeout)
  File "C:\Python34\lib\urllib\request.py", line 461, in open
    response = meth(req, response)
  File "C:\Python34\lib\urllib\request.py", line 571, in http_response
    'http', request, response, code, msg, hdrs)
  File "C:\Python34\lib\urllib\request.py", line 499, in error
    return self._call_chain(*args)
  File "C:\Python34\lib\urllib\request.py", line 433, in _call_chain
    result = func(*args)
  File "C:\Python34\lib\urllib\request.py", line 579, in http_error_default
    raise HTTPError(req.full_url, code, msg, hdrs, fp)
urllib.error.HTTPError: HTTP Error 404: Not Found
[EXCEPTION] [2015-02-18|10:40:21] Traceback (most recent call last):
  File "C:\Users\PD\Documents\polly\pythonDongle\remote_monitor.py", line 15, in send_request
    wp = urllib2.urlopen(http_request, timeout=d.web_request_timeout)
  File "C:\Python34\lib\urllib\request.py", line 153, in urlopen
    return opener.open(url, data, timeout)
  File "C:\Python34\lib\urllib\request.py", line 461, in open
    response = meth(req, response)
  File "C:\Python34\lib\urllib\request.py", line 571, in http_response
    'http', request, response, code, msg, hdrs)
  File "C:\Python34\lib\urllib\request.py", line 499, in error
    return self._call_chain(*args)
  File "C:\Python34\lib\urllib\request.py", line 433, in _call_chain
    result = func(*args)
  File "C:\Python34\lib\urllib\request.py", line 579, in http_error_default
    raise HTTPError(req.full_url, code, msg, hdrs, fp)
urllib.error.HTTPError: HTTP Error 404: Not Found
[EXCEPTION] [2015-02-18|10:40:21] Traceback (most recent call last):
  File "C:\Users\PD\Documents\polly\pythonDongle\remote_monitor.py", line 15, in send_request
    wp = urllib2.urlopen(http_request, timeout=d.web_request_timeout)
  File "C:\Python34\lib\urllib\request.py", line 153, in urlopen
    return opener.open(url, data, timeout)
  File "C:\Python34\lib\urllib\request.py", line 461, in open
    response = meth(req, response)
  File "C:\Python34\lib\urllib\request.py", line 571, in http_response
    'http', request, response, code, msg, hdrs)
  File "C:\Python34\lib\urllib\request.py", line 499, in error
    return self._call_chain(*args)
  File "C:\Python34\lib\urllib\request.py", line 433, in _call_chain
    result = func(*args)
  File "C:\Python34\lib\urllib\request.py", line 579, in http_error_default
    raise HTTPError(req.full_url, code, msg, hdrs, fp)
urllib.error.HTTPError: HTTP Error 404: Not Found
[EXCEPTION] [2015-02-18|10:40:21] URL Error... Timeout?
HTTP Error 404: Not Found
[EXCEPTION] [2015-02-18|10:40:21] >>>> Retrying request: http://128.2.211.183/wa/RemoteMonitor/dongleMontiorUpdate.php?update=TE9HO1tDT00xNl0gWzIwMTUtMDItMTh8MTA6NDA6MThdIFNlbmRpbmcga2VlcC1hbGl2ZSBtZXNzYWdlIHRvIHNlcnZlci4uLg==
[EXCEPTION] [2015-02-18|10:40:21] >>>> Retrying request: http://128.2.211.183/wa/RemoteMonitor/dongleMontiorUpdate.php?update=TE9HO1tDT00xNl0gWzIwMTUtMDItMTh8MTA6NDA6MThdIFNlbmRpbmcga2VlcC1hbGl2ZSBtZXNzYWdlIHRvIHNlcnZlci4uLg==
[EXCEPTION] [2015-02-18|10:40:21] >>>> Retrying request: http://128.2.211.183/wa/RemoteMonitor/dongleMontiorUpdate.php?update=TE9HO1tDT00xNl0gWzIwMTUtMDItMTh8MTA6NDA6MThdIFNlbmRpbmcga2VlcC1hbGl2ZSBtZXNzYWdlIHRvIHNlcnZlci4uLg==
[EXCEPTION] [2015-02-18|10:40:21] Traceback (most recent call last):
  File "C:\Users\PD\Documents\polly\pythonDongle\remote_monitor.py", line 15, in send_request
    wp = urllib2.urlopen(http_request, timeout=d.web_request_timeout)
  File "C:\Python34\lib\urllib\request.py", line 153, in urlopen
    return opener.open(url, data, timeout)
  File "C:\Python34\lib\urllib\request.py", line 461, in open
    response = meth(req, response)
  File "C:\Python34\lib\urllib\request.py", line 571, in http_response
    'http', request, response, code, msg, hdrs)
  File "C:\Python34\lib\urllib\request.py", line 499, in error
    return self._call_chain(*args)
  File "C:\Python34\lib\urllib\request.py", line 433, in _call_chain
    result = func(*args)
  File "C:\Python34\lib\urllib\request.py", line 579, in http_error_default
    raise HTTPError(req.full_url, code, msg, hdrs, fp)
urllib.error.HTTPError: HTTP Error 404: Not Found
[EXCEPTION] [2015-02-18|10:40:21] URL Error... Timeout?
HTTP Error 404: Not Found
[EXCEPTION] [2015-02-18|10:40:21] URL Error... Timeout?
HTTP Error 404: Not Found
[EXCEPTION] [2015-02-18|10:40:21] URL Error... Timeout?
HTTP Error 404: Not Found
[EXCEPTION] [2015-02-18|10:40:22] Traceback (most recent call last):
  File "C:\Users\PD\Documents\polly\pythonDongle\remote_monitor.py", line 15, in send_request
    wp = urllib2.urlopen(http_request, timeout=d.web_request_timeout)
  File "C:\Python34\lib\urllib\request.py", line 153, in urlopen
    return opener.open(url, data, timeout)
  File "C:\Python34\lib\urllib\request.py", line 461, in open
    response = meth(req, response)
  File "C:\Python34\lib\urllib\request.py", line 571, in http_response
    'http', request, response, code, msg, hdrs)
  File "C:\Python34\lib\urllib\request.py", line 499, in error
    return self._call_chain(*args)
  File "C:\Python34\lib\urllib\request.py", line 433, in _call_chain
    result = func(*args)
  File "C:\Python34\lib\urllib\request.py", line 579, in http_error_default
    raise HTTPError(req.full_url, code, msg, hdrs, fp)
urllib.error.HTTPError: HTTP Error 404: Not Found
[EXCEPTION] [2015-02-18|10:40:22] Traceback (most recent call last):
  File "C:\Users\PD\Documents\polly\pythonDongle\remote_monitor.py", line 15, in send_request
    wp = urllib2.urlopen(http_request, timeout=d.web_request_timeout)
  File "C:\Python34\lib\urllib\request.py", line 153, in urlopen
    return opener.open(url, data, timeout)
  File "C:\Python34\lib\urllib\request.py", line 461, in open
    response = meth(req, response)
  File "C:\Python34\lib\urllib\request.py", line 571, in http_response
    'http', request, response, code, msg, hdrs)
  File "C:\Python34\lib\urllib\request.py", line 499, in error
    return self._call_chain(*args)
  File "C:\Python34\lib\urllib\request.py", line 433, in _call_chain
    result = func(*args)
  File "C:\Python34\lib\urllib\request.py", line 579, in http_error_default
    raise HTTPError(req.full_url, code, msg, hdrs, fp)
urllib.error.HTTPError: HTTP Error 404: Not Found
[EXCEPTION] [2015-02-18|10:40:22] URL Error... Timeout?
HTTP Error 404: Not Found
[EXCEPTION] [2015-02-18|10:40:22] Traceback (most recent call last):
  File "C:\Users\PD\Documents\polly\pythonDongle\remote_monitor.py", line 15, in send_request
    wp = urllib2.urlopen(http_request, timeout=d.web_request_timeout)
  File "C:\Python34\lib\urllib\request.py", line 153, in urlopen
    return opener.open(url, data, timeout)
  File "C:\Python34\lib\urllib\request.py", line 461, in open
    response = meth(req, response)
  File "C:\Python34\lib\urllib\request.py", line 571, in http_response
    'http', request, response, code, msg, hdrs)
  File "C:\Python34\lib\urllib\request.py", line 499, in error
    return self._call_chain(*args)
  File "C:\Python34\lib\urllib\request.py", line 433, in _call_chain
    result = func(*args)
  File "C:\Python34\lib\urllib\request.py", line 579, in http_error_default
    raise HTTPError(req.full_url, code, msg, hdrs, fp)
urllib.error.HTTPError: HTTP Error 404: Not Found
[EXCEPTION] [2015-02-18|10:40:22] Traceback (most recent call last):
  File "C:\Users\PD\Documents\polly\pythonDongle\remote_monitor.py", line 15, in send_request
    wp = urllib2.urlopen(http_request, timeout=d.web_request_timeout)
  File "C:\Python34\lib\urllib\request.py", line 153, in urlopen
    return opener.open(url, data, timeout)
  File "C:\Python34\lib\urllib\request.py", line 461, in open
    response = meth(req, response)
  File "C:\Python34\lib\urllib\request.py", line 571, in http_response
    'http', request, response, code, msg, hdrs)
  File "C:\Python34\lib\urllib\request.py", line 499, in error
    return self._call_chain(*args)
  File "C:\Python34\lib\urllib\request.py", line 433, in _call_chain
    result = func(*args)
  File "C:\Python34\lib\urllib\request.py", line 579, in http_error_default
    raise HTTPError(req.full_url, code, msg, hdrs, fp)
urllib.error.HTTPError: HTTP Error 404: Not Found
[EXCEPTION] [2015-02-18|10:40:22] >>>> Retrying request: http://128.2.211.183/wa/RemoteMonitor/dongleMontiorUpdate.php?update=TE9HO1JTU0k6IDEy
[EXCEPTION] [2015-02-18|10:40:22] URL Error... Timeout?
HTTP Error 404: Not Found
[EXCEPTION] [2015-02-18|10:40:22] Traceback (most recent call last):
  File "C:\Users\PD\Documents\polly\pythonDongle\remote_monitor.py", line 15, in send_request
    wp = urllib2.urlopen(http_request, timeout=d.web_request_timeout)
  File "C:\Python34\lib\urllib\request.py", line 153, in urlopen
    return opener.open(url, data, timeout)
  File "C:\Python34\lib\urllib\request.py", line 461, in open
    response = meth(req, response)
  File "C:\Python34\lib\urllib\request.py", line 571, in http_response
    'http', request, response, code, msg, hdrs)
  File "C:\Python34\lib\urllib\request.py", line 499, in error
    return self._call_chain(*args)
  File "C:\Python34\lib\urllib\request.py", line 433, in _call_chain
    result = func(*args)
  File "C:\Python34\lib\urllib\request.py", line 579, in http_error_default
    raise HTTPError(req.full_url, code, msg, hdrs, fp)
urllib.error.HTTPError: HTTP Error 404: Not Found
[EXCEPTION] [2015-02-18|10:40:22] >>>> Retrying request: http://128.2.211.183/wa/RemoteMonitor/dongleMontiorUpdate.php?update=TE9HO0RFVklDRSBTVEFURTogUkVBRFk=
[EXCEPTION] [2015-02-18|10:40:22] URL Error... Timeout?
HTTP Error 404: Not Found
[EXCEPTION] [2015-02-18|10:40:22] Traceback (most recent call last):
  File "C:\Users\PD\Documents\polly\pythonDongle\remote_monitor.py", line 15, in send_request
    wp = urllib2.urlopen(http_request, timeout=d.web_request_timeout)
  File "C:\Python34\lib\urllib\request.py", line 153, in urlopen
    return opener.open(url, data, timeout)
  File "C:\Python34\lib\urllib\request.py", line 461, in open
    response = meth(req, response)
  File "C:\Python34\lib\urllib\request.py", line 571, in http_response
    'http', request, response, code, msg, hdrs)
  File "C:\Python34\lib\urllib\request.py", line 499, in error
    return self._call_chain(*args)
  File "C:\Python34\lib\urllib\request.py", line 433, in _call_chain
    result = func(*args)
  File "C:\Python34\lib\urllib\request.py", line 579, in http_error_default
    raise HTTPError(req.full_url, code, msg, hdrs, fp)
urllib.error.HTTPError: HTTP Error 404: Not Found
[EXCEPTION] [2015-02-18|10:40:22] >>>> Retrying request: http://128.2.211.183/wa/RemoteMonitor/dongleMontiorUpdate.php?update=TE9HO0NBUlJJRVI6IENlbGxjb20gR04=
[EXCEPTION] [2015-02-18|10:40:22] URL Error... Timeout?
HTTP Error 404: Not Found
[EXCEPTION] [2015-02-18|10:40:22] Traceback (most recent call last):
  File "C:\Users\PD\Documents\polly\pythonDongle\remote_monitor.py", line 15, in send_request
    wp = urllib2.urlopen(http_request, timeout=d.web_request_timeout)
  File "C:\Python34\lib\urllib\request.py", line 153, in urlopen
    return opener.open(url, data, timeout)
  File "C:\Python34\lib\urllib\request.py", line 461, in open
    response = meth(req, response)
  File "C:\Python34\lib\urllib\request.py", line 571, in http_response
    'http', request, response, code, msg, hdrs)
  File "C:\Python34\lib\urllib\request.py", line 499, in error
    return self._call_chain(*args)
  File "C:\Python34\lib\urllib\request.py", line 433, in _call_chain
    result = func(*args)
  File "C:\Python34\lib\urllib\request.py", line 579, in http_error_default
    raise HTTPError(req.full_url, code, msg, hdrs, fp)
urllib.error.HTTPError: HTTP Error 404: Not Found
[EXCEPTION] [2015-02-18|10:40:22] >>>> Retrying request: http://128.2.211.183/wa/RemoteMonitor/dongleMontiorUpdate.php?update=TE9HOytDT1BTIFJlc3BvbnNlOiBBVCtDT1BTPw0NCitDT1BTOiAwLDAsIkNlbGxjb20gR04iLDINCg0KT0sNCg==
[EXCEPTION] [2015-02-18|10:40:22] URL Error... Timeout?
HTTP Error 404: Not Found
[EXCEPTION] [2015-02-18|10:40:22] Traceback (most recent call last):
  File "C:\Users\PD\Documents\polly\pythonDongle\remote_monitor.py", line 15, in send_request
    wp = urllib2.urlopen(http_request, timeout=d.web_request_timeout)
  File "C:\Python34\lib\urllib\request.py", line 153, in urlopen
    return opener.open(url, data, timeout)
  File "C:\Python34\lib\urllib\request.py", line 461, in open
    response = meth(req, response)
  File "C:\Python34\lib\urllib\request.py", line 571, in http_response
    'http', request, response, code, msg, hdrs)
  File "C:\Python34\lib\urllib\request.py", line 499, in error
    return self._call_chain(*args)
  File "C:\Python34\lib\urllib\request.py", line 433, in _call_chain
    result = func(*args)
  File "C:\Python34\lib\urllib\request.py", line 579, in http_error_default
    raise HTTPError(req.full_url, code, msg, hdrs, fp)
urllib.error.HTTPError: HTTP Error 404: Not Found
[EXCEPTION] [2015-02-18|10:44:47] >>>> Retrying request: http://128.2.211.183/wa/RemoteMonitor/dongleMontiorUpdate.php?update=TE9HO0RFVklDRSBTVEFURTogUkVBRFk=
[EXCEPTION] [2015-02-18|10:44:48] >>>> Retrying request: http://128.2.211.183/wa/RemoteMonitor/dongleMontiorUpdate.php?update=QUxJVkU7WzIwMTUtMDItMTh8MTA6NDA6MTldOzE7MTI7Q2VsbGNvbSBHTjtSRUFEWTtDT00xNg==
[EXCEPTION] [2015-02-18|10:44:48] >>>> Retrying request: http://128.2.211.183/wa/RemoteMonitor/dongleMontiorUpdate.php?update=TE9HOytDU1EgUmVzcG9uc2U6IEFUK0NTUQ0NCitDU1E6IDEyLDk5DQoNCk9LDQo=
[EXCEPTION] [2015-02-18|10:44:48] >>>> Retrying request: http://128.2.211.183/wa/RemoteMonitor/dongleMontiorUpdate.php?update=TE9HOytDT1BTIFJlc3BvbnNlOiBBVCtDT1BTPw0NCitDT1BTOiAwLDAsIkNlbGxjb20gR04iLDINCg0KT0sNCg==
[EXCEPTION] [2015-02-18|10:44:48] >>>> Retrying request: http://128.2.211.183/wa/RemoteMonitor/dongleMontiorUpdate.php?update=TE9HOytDU1EgUmVzcG9uc2U6IEFUK0NTUQ0NCitDU1E6IDEyLDk5DQoNCk9LDQo=
[EXCEPTION] [2015-02-18|10:44:49] >>>> Retrying request: http://128.2.211.183/wa/RemoteMonitor/dongleMontiorUpdate.php?update=TE9HOytDUEFTIFJlc3BvbnNlOiBBVCtDUEFTDQ0KK0NQQVM6IDANCg0KT0sNCg==
[EXCEPTION] [2015-02-18|10:44:49] >>>> Retrying request: http://128.2.211.183/wa/RemoteMonitor/dongleMontiorUpdate.php?update=TE9HOytDUEFTIFJlc3BvbnNlOiBBVCtDUEFTDQ0KK0NQQVM6IDANCg0KT0sNCg==
[EXCEPTION] [2015-02-18|10:44:49] >>>> Retrying request: http://128.2.211.183/wa/RemoteMonitor/dongleMontiorUpdate.php?update=QUxJVkU7WzIwMTUtMDItMTh8MTA6NDA6MTVdOzE7MTI7Q2VsbGNvbSBHTjtSRUFEWTtDT00xNw==
[EXCEPTION] [2015-02-18|10:44:50] >>>> Retrying request: http://128.2.211.183/wa/RemoteMonitor/dongleMontiorUpdate.php?update=QUxJVkU7WzIwMTUtMDItMTh8MTA6NDA6MTRdOzE7MTI7Q2VsbGNvbSBHTjtSRUFEWTtDT00yMA==
[EXCEPTION] [2015-02-18|10:44:50] >>>> Retrying request: http://128.2.211.183/wa/RemoteMonitor/dongleMontiorUpdate.php?update=TE9HOytDT1BTIFJlc3BvbnNlOiBBVCtDT1BTPw0NCitDT1BTOiAwLDAsIkNlbGxjb20gR04iLDINCg0KT0sNCg==
[EXCEPTION] [2015-02-18|10:44:50] >>>> Retrying request: http://128.2.211.183/wa/RemoteMonitor/dongleMontiorUpdate.php?update=TE9HOytDUEFTIFJlc3BvbnNlOiBBVCtDUEFTDQ0KK0NQQVM6IDANCg0KT0sNCg==
[EXCEPTION] [2015-02-18|10:44:51] >>>> Retrying request: http://128.2.211.183/wa/RemoteMonitor/dongleMontiorUpdate.php?update=TE9HOytDUEFTIFJlc3BvbnNlOiBBVCtDUEFTDQ0KK0NQQVM6IDANCg0KT0sNCg==
[EXCEPTION] [2015-02-18|10:44:51] >>>> Retrying request: http://128.2.211.183/wa/RemoteMonitor/dongleMontiorUpdate.php?update=TE9HOytDUEFTIFJlc3BvbnNlOiBBVCtDUEFTDQ0KK0NQQVM6IDANCg0KT0sNCg==
[EXCEPTION] [2015-02-18|10:44:51] >>>> Retrying request: http://128.2.211.183/wa/RemoteMonitor/dongleMontiorUpdate.php?update=TE9HOytDUEFTIFJlc3BvbnNlOiBBVCtDUEFTDQ0KK0NQQVM6IDANCg0KT0sNCg==
[EXCEPTION] [2015-02-18|10:44:51] >>>> Retrying request: http://128.2.211.183/wa/RemoteMonitor/dongleMontiorUpdate.php?update=TE9HOytDUEFTIFJlc3BvbnNlOiBBVCtDUEFTDQ0KK0NQQVM6IDANCg0KT0sNCg==
[EXCEPTION] [2015-02-18|10:44:52] >>>> Retrying request: http://128.2.211.183/wa/RemoteMonitor/dongleMontiorUpdate.php?update=TE9HO1JTU0k6IDEy
[EXCEPTION] [2015-02-18|10:44:52] >>>> Retrying request: http://128.2.211.183/wa/RemoteMonitor/dongleMontiorUpdate.php?update=TE9HO0NBUlJJRVI6IENlbGxjb20gR04=
[EXCEPTION] [2015-02-18|10:44:52] >>>> Retrying request: http://128.2.211.183/wa/RemoteMonitor/dongleMontiorUpdate.php?update=TE9HO0RFVklDRSBTVEFURTogUkVBRFk=
[EXCEPTION] [2015-02-18|10:44:53] >>>> Retrying request: http://128.2.211.183/wa/RemoteMonitor/dongleMontiorUpdate.php?update=TE9HO0RFVklDRSBTVEFURTogUkVBRFk=
[EXCEPTION] [2015-02-18|10:44:53] >>>> Retrying request: http://128.2.211.183/wa/RemoteMonitor/dongleMontiorUpdate.php?update=TE9HO0NBUlJJRVI6IENlbGxjb20gR04=
[EXCEPTION] [2015-02-18|10:44:53] >>>> Retrying request: http://128.2.211.183/wa/RemoteMonitor/dongleMontiorUpdate.php?update=TE9HO0RFVklDRSBTVEFURTogUkVBRFk=
[EXCEPTION] [2015-02-18|10:44:53] >>>> Retrying request: http://128.2.211.183/wa/RemoteMonitor/dongleMontiorUpdate.php?update=TE9HO0RFVklDRSBTVEFURTogUkVBRFk=
[EXCEPTION] [2015-02-18|10:44:54] >>>> Retrying request: http://128.2.211.183/wa/RemoteMonitor/dongleMontiorUpdate.php?update=TE9HO0RFVklDRSBTVEFURTogUkVBRFk=
[EXCEPTION] [2015-02-18|10:44:54] >>>> Retrying request: http://128.2.211.183/wa/RemoteMonitor/dongleMontiorUpdate.php?update=QUxJVkU7WzIwMTUtMDItMTh8MTA6NDA6MTVdOzE7MTI7Q2VsbGNvbSBHTjtSRUFEWTtDT00yMg==
[EXCEPTION] [2015-02-18|10:44:54] >>>> Retrying request: http://128.2.211.183/wa/RemoteMonitor/dongleMontiorUpdate.php?update=TE9HO0NBUlJJRVI6IENlbGxjb20gR04=
[EXCEPTION] [2015-02-18|10:44:55] >>>> Retrying request: http://128.2.211.183/wa/RemoteMonitor/dongleMontiorUpdate.php?update=TE9HOytDU1EgUmVzcG9uc2U6IEFUK0NTUQ0NCitDU1E6IDEyLDk5DQoNCk9LDQo=
[EXCEPTION] [2015-02-18|10:44:55] >>>> Retrying request: http://128.2.211.183/wa/RemoteMonitor/dongleMontiorUpdate.php?update=TE9HOytDU1EgUmVzcG9uc2U6IEFUK0NTUQ0NCitDU1E6IDEyLDk5DQoNCk9LDQo=
[EXCEPTION] [2015-02-18|10:44:55] >>>> Retrying request: http://128.2.211.183/wa/RemoteMonitor/dongleMontiorUpdate.php?update=TE9HOytDU1EgUmVzcG9uc2U6IEFUK0NTUQ0NCitDU1E6IDEyLDk5DQoNCk9LDQo=
[EXCEPTION] [2015-02-18|10:44:55] >>>> Retrying request: http://128.2.211.183/wa/RemoteMonitor/dongleMontiorUpdate.php?update=TE9HOytDU1EgUmVzcG9uc2U6IEFUK0NTUQ0NCitDU1E6IDEyLDk5DQoNCk9LDQo=
[EXCEPTION] [2015-02-18|10:44:56] >>>> Retrying request: http://128.2.211.183/wa/RemoteMonitor/dongleMontiorUpdate.php?update=TE9HOytDU1EgUmVzcG9uc2U6IEFUK0NTUQ0NCitDU1E6IDEyLDk5DQoNCk9LDQo=
[EXCEPTION] [2015-02-18|10:44:56] >>>> Retrying request: http://128.2.211.183/wa/RemoteMonitor/dongleMontiorUpdate.php?update=TE9HO1tDT00xNl0gWzIwMTUtMDItMTh8MTA6NDA6MThdIFNlbmRpbmcga2VlcC1hbGl2ZSBtZXNzYWdlIHRvIHNlcnZlci4uLg==
[EXCEPTION] [2015-02-18|10:44:56] >>>> Retrying request: http://128.2.211.183/wa/RemoteMonitor/dongleMontiorUpdate.php?update=TE9HO1tDT00xNl0gWzIwMTUtMDItMTh8MTA6NDA6MThdIFNlbmRpbmcga2VlcC1hbGl2ZSBtZXNzYWdlIHRvIHNlcnZlci4uLg==
[EXCEPTION] [2015-02-18|10:44:57] >>>> Retrying request: http://128.2.211.183/wa/RemoteMonitor/dongleMontiorUpdate.php?update=TE9HO1tDT00xNl0gWzIwMTUtMDItMTh8MTA6NDA6MThdIFNlbmRpbmcga2VlcC1hbGl2ZSBtZXNzYWdlIHRvIHNlcnZlci4uLg==
[EXCEPTION] [2015-02-18|10:44:57] >>>> Retrying request: http://128.2.211.183/wa/RemoteMonitor/dongleMontiorUpdate.php?update=TE9HO1tDT00xNl0gWzIwMTUtMDItMTh8MTA6NDA6MThdIFNlbmRpbmcga2VlcC1hbGl2ZSBtZXNzYWdlIHRvIHNlcnZlci4uLg==
[EXCEPTION] [2015-02-18|10:44:57] >>>> Retrying request: http://128.2.211.183/wa/RemoteMonitor/dongleMontiorUpdate.php?update=TE9HO1tDT00xNl0gWzIwMTUtMDItMTh8MTA6NDA6MThdIFNlbmRpbmcga2VlcC1hbGl2ZSBtZXNzYWdlIHRvIHNlcnZlci4uLg==
[EXCEPTION] [2015-02-18|10:44:58] >>>> Retrying request: http://128.2.211.183/wa/RemoteMonitor/dongleMontiorUpdate.php?update=TE9HO1JTU0k6IDEy
[EXCEPTION] [2015-02-18|10:44:58] >>>> Retrying request: http://128.2.211.183/wa/RemoteMonitor/dongleMontiorUpdate.php?update=TE9HO0RFVklDRSBTVEFURTogUkVBRFk=
[EXCEPTION] [2015-02-18|10:44:58] >>>> Retrying request: http://128.2.211.183/wa/RemoteMonitor/dongleMontiorUpdate.php?update=TE9HO0NBUlJJRVI6IENlbGxjb20gR04=
[EXCEPTION] [2015-02-18|10:44:58] >>>> Retrying request: http://128.2.211.183/wa/RemoteMonitor/dongleMontiorUpdate.php?update=TE9HOytDT1BTIFJlc3BvbnNlOiBBVCtDT1BTPw0NCitDT1BTOiAwLDAsIkNlbGxjb20gR04iLDINCg0KT0sNCg==
[EXCEPTION] [2015-02-18|13:46:51] An Exception occurred!
''
[EXCEPTION] [2015-02-18|13:46:51] Traceback (most recent call last):
  File "C:\Users\PD\Documents\polly\pythonDongle\remote_monitor.py", line 15, in send_request
    wp = urllib2.urlopen(http_request, timeout=d.web_request_timeout)
  File "C:\Python34\lib\urllib\request.py", line 153, in urlopen
    return opener.open(url, data, timeout)
  File "C:\Python34\lib\urllib\request.py", line 455, in open
    response = self._open(req, data)
  File "C:\Python34\lib\urllib\request.py", line 473, in _open
    '_open', req)
  File "C:\Python34\lib\urllib\request.py", line 433, in _call_chain
    result = func(*args)
  File "C:\Python34\lib\urllib\request.py", line 1215, in http_open
    return self.do_open(http.client.HTTPConnection, req)
  File "C:\Python34\lib\urllib\request.py", line 1194, in do_open
    r = h.getresponse()
  File "C:\Python34\lib\http\client.py", line 1172, in getresponse
    response.begin()
  File "C:\Python34\lib\http\client.py", line 351, in begin
    version, status, reason = self._read_status()
  File "C:\Python34\lib\http\client.py", line 321, in _read_status
    raise BadStatusLine(line)
http.client.BadStatusLine: ''
[EXCEPTION] [2015-02-18|13:46:51] Moving on... Tired of getting SMSs about this...
[EXCEPTION] [2015-02-18|13:49:47] >>>> Retrying request: http://128.2.211.183/wa/RemoteMonitor/dongleMontiorUpdate.php?update=TE9HOytDUEFTIFJlc3BvbnNlOiBBVCtDUEFTDQ0KK0NQQVM6IDANCg0KT0sNCg==
[EXCEPTION] [2015-02-18|22:25:19] An Exception occurred!
''
[EXCEPTION] [2015-02-18|22:25:20] Traceback (most recent call last):
  File "C:\Users\PD\Documents\polly\pythonDongle\remote_monitor.py", line 15, in send_request
    wp = urllib2.urlopen(http_request, timeout=d.web_request_timeout)
  File "C:\Python34\lib\urllib\request.py", line 153, in urlopen
    return opener.open(url, data, timeout)
  File "C:\Python34\lib\urllib\request.py", line 455, in open
    response = self._open(req, data)
  File "C:\Python34\lib\urllib\request.py", line 473, in _open
    '_open', req)
  File "C:\Python34\lib\urllib\request.py", line 433, in _call_chain
    result = func(*args)
  File "C:\Python34\lib\urllib\request.py", line 1215, in http_open
    return self.do_open(http.client.HTTPConnection, req)
  File "C:\Python34\lib\urllib\request.py", line 1194, in do_open
    r = h.getresponse()
  File "C:\Python34\lib\http\client.py", line 1172, in getresponse
    response.begin()
  File "C:\Python34\lib\http\client.py", line 351, in begin
    version, status, reason = self._read_status()
  File "C:\Python34\lib\http\client.py", line 321, in _read_status
    raise BadStatusLine(line)
http.client.BadStatusLine: ''
[EXCEPTION] [2015-02-18|22:25:20] Moving on... Tired of getting SMSs about this...
[EXCEPTION] [2015-02-18|22:25:20] >>>> Retrying request: http://128.2.211.183/wa/RemoteMonitor/dongleMontiorUpdate.php?update=TE9HOytDUEFTIFJlc3BvbnNlOiBBVCtDUEFTDQ0KK0NQQVM6IDANCg0KT0sNCg==
