STARTED:[2015-02-23|13:03:12]
[EXCEPTION] [2015-02-23|13:03:12] An Exception occurred!
''
[EXCEPTION] [2015-02-23|13:03:12] Traceback (most recent call last):
  File "C:\Users\PD\Documents\polly\pythonDongle\remote_monitor.py", line 15, in send_request
    wp = urllib2.urlopen(http_request, timeout=d.web_request_timeout)
  File "C:\Python34\lib\urllib\request.py", line 153, in urlopen
    return opener.open(url, data, timeout)
  File "C:\Python34\lib\urllib\request.py", line 455, in open
    response = self._open(req, data)
  File "C:\Python34\lib\urllib\request.py", line 473, in _open
    '_open', req)
  File "C:\Python34\lib\urllib\request.py", line 433, in _call_chain
    result = func(*args)
  File "C:\Python34\lib\urllib\request.py", line 1215, in http_open
    return self.do_open(http.client.HTTPConnection, req)
  File "C:\Python34\lib\urllib\request.py", line 1194, in do_open
    r = h.getresponse()
  File "C:\Python34\lib\http\client.py", line 1172, in getresponse
    response.begin()
  File "C:\Python34\lib\http\client.py", line 351, in begin
    version, status, reason = self._read_status()
  File "C:\Python34\lib\http\client.py", line 321, in _read_status
    raise BadStatusLine(line)
http.client.BadStatusLine: ''
[EXCEPTION] [2015-02-23|13:03:12] Moving on... Tired of getting SMSs about this...
[EXCEPTION] [2015-02-23|13:03:12] >>>> Retrying request: http://128.2.211.183/wa/RemoteMonitor/dongleMontiorUpdate.php?update=QUxJVkU7WzIwMTUtMDItMjN8MTM6MDM6MTFdOzE7MTQ7Q2VsbGNvbSBHTjtSRUFEWTtDT00yMg==
[EXCEPTION] [2015-02-23|13:47:05] URL Error... Timeout?
<urlopen error [WinError 10060] A connection attempt failed because the connected party did not properly respond after a period of time, or established connection failed because connected host has failed to respond>
[EXCEPTION] [2015-02-23|13:47:05] Traceback (most recent call last):
  File "C:\Python34\lib\urllib\request.py", line 1189, in do_open
    h.request(req.get_method(), req.selector, req.data, headers)
  File "C:\Python34\lib\http\client.py", line 1090, in request
    self._send_request(method, url, body, headers)
  File "C:\Python34\lib\http\client.py", line 1128, in _send_request
    self.endheaders(body)
  File "C:\Python34\lib\http\client.py", line 1086, in endheaders
    self._send_output(message_body)
  File "C:\Python34\lib\http\client.py", line 924, in _send_output
    self.send(msg)
  File "C:\Python34\lib\http\client.py", line 859, in send
    self.connect()
  File "C:\Python34\lib\http\client.py", line 836, in connect
    self.timeout, self.source_address)
  File "C:\Python34\lib\socket.py", line 509, in create_connection
    raise err
  File "C:\Python34\lib\socket.py", line 500, in create_connection
    sock.connect(sa)
TimeoutError: [WinError 10060] A connection attempt failed because the connected party did not properly respond after a period of time, or established connection failed because connected host has failed to respond

During handling of the above exception, another exception occurred:

Traceback (most recent call last):
  File "C:\Users\PD\Documents\polly\pythonDongle\remote_monitor.py", line 15, in send_request
    wp = urllib2.urlopen(http_request, timeout=d.web_request_timeout)
  File "C:\Python34\lib\urllib\request.py", line 153, in urlopen
    return opener.open(url, data, timeout)
  File "C:\Python34\lib\urllib\request.py", line 455, in open
    response = self._open(req, data)
  File "C:\Python34\lib\urllib\request.py", line 473, in _open
    '_open', req)
  File "C:\Python34\lib\urllib\request.py", line 433, in _call_chain
    result = func(*args)
  File "C:\Python34\lib\urllib\request.py", line 1215, in http_open
    return self.do_open(http.client.HTTPConnection, req)
  File "C:\Python34\lib\urllib\request.py", line 1192, in do_open
    raise URLError(err)
urllib.error.URLError: <urlopen error [WinError 10060] A connection attempt failed because the connected party did not properly respond after a period of time, or established connection failed because connected host has failed to respond>
[EXCEPTION] [2015-02-23|13:49:47] >>>> Retrying request: http://128.2.211.183/wa/RemoteMonitor/dongleMontiorUpdate.php?update=QUxJVkU7WzIwMTUtMDItMjN8MTM6NDY6NDNdOzE7MTQ7Q2VsbGNvbSBHTjtSRUFEWTtDT00yMg==
[EXCEPTION] [2015-02-23|13:58:02] URL Error... Timeout?
<urlopen error [WinError 10060] A connection attempt failed because the connected party did not properly respond after a period of time, or established connection failed because connected host has failed to respond>
[EXCEPTION] [2015-02-23|13:58:02] Traceback (most recent call last):
  File "C:\Python34\lib\urllib\request.py", line 1189, in do_open
    h.request(req.get_method(), req.selector, req.data, headers)
  File "C:\Python34\lib\http\client.py", line 1090, in request
    self._send_request(method, url, body, headers)
  File "C:\Python34\lib\http\client.py", line 1128, in _send_request
    self.endheaders(body)
  File "C:\Python34\lib\http\client.py", line 1086, in endheaders
    self._send_output(message_body)
  File "C:\Python34\lib\http\client.py", line 924, in _send_output
    self.send(msg)
  File "C:\Python34\lib\http\client.py", line 859, in send
    self.connect()
  File "C:\Python34\lib\http\client.py", line 836, in connect
    self.timeout, self.source_address)
  File "C:\Python34\lib\socket.py", line 509, in create_connection
    raise err
  File "C:\Python34\lib\socket.py", line 500, in create_connection
    sock.connect(sa)
TimeoutError: [WinError 10060] A connection attempt failed because the connected party did not properly respond after a period of time, or established connection failed because connected host has failed to respond

During handling of the above exception, another exception occurred:

Traceback (most recent call last):
  File "C:\Users\PD\Documents\polly\pythonDongle\remote_monitor.py", line 15, in send_request
    wp = urllib2.urlopen(http_request, timeout=d.web_request_timeout)
  File "C:\Python34\lib\urllib\request.py", line 153, in urlopen
    return opener.open(url, data, timeout)
  File "C:\Python34\lib\urllib\request.py", line 455, in open
    response = self._open(req, data)
  File "C:\Python34\lib\urllib\request.py", line 473, in _open
    '_open', req)
  File "C:\Python34\lib\urllib\request.py", line 433, in _call_chain
    result = func(*args)
  File "C:\Python34\lib\urllib\request.py", line 1215, in http_open
    return self.do_open(http.client.HTTPConnection, req)
  File "C:\Python34\lib\urllib\request.py", line 1192, in do_open
    raise URLError(err)
urllib.error.URLError: <urlopen error [WinError 10060] A connection attempt failed because the connected party did not properly respond after a period of time, or established connection failed because connected host has failed to respond>
[EXCEPTION] [2015-02-23|13:59:47] >>>> Retrying request: http://128.2.211.183/wa/RemoteMonitor/dongleMontiorUpdate.php?update=TE9HO0NBUlJJRVI6IENlbGxjb20gR04=
[EXCEPTION] [2015-02-23|14:03:31] URL Error... Timeout?
<urlopen error [WinError 10060] A connection attempt failed because the connected party did not properly respond after a period of time, or established connection failed because connected host has failed to respond>
[EXCEPTION] [2015-02-23|14:03:31] Traceback (most recent call last):
  File "C:\Python34\lib\urllib\request.py", line 1189, in do_open
    h.request(req.get_method(), req.selector, req.data, headers)
  File "C:\Python34\lib\http\client.py", line 1090, in request
    self._send_request(method, url, body, headers)
  File "C:\Python34\lib\http\client.py", line 1128, in _send_request
    self.endheaders(body)
  File "C:\Python34\lib\http\client.py", line 1086, in endheaders
    self._send_output(message_body)
  File "C:\Python34\lib\http\client.py", line 924, in _send_output
    self.send(msg)
  File "C:\Python34\lib\http\client.py", line 859, in send
    self.connect()
  File "C:\Python34\lib\http\client.py", line 836, in connect
    self.timeout, self.source_address)
  File "C:\Python34\lib\socket.py", line 509, in create_connection
    raise err
  File "C:\Python34\lib\socket.py", line 500, in create_connection
    sock.connect(sa)
TimeoutError: [WinError 10060] A connection attempt failed because the connected party did not properly respond after a period of time, or established connection failed because connected host has failed to respond

During handling of the above exception, another exception occurred:

Traceback (most recent call last):
  File "C:\Users\PD\Documents\polly\pythonDongle\remote_monitor.py", line 15, in send_request
    wp = urllib2.urlopen(http_request, timeout=d.web_request_timeout)
  File "C:\Python34\lib\urllib\request.py", line 153, in urlopen
    return opener.open(url, data, timeout)
  File "C:\Python34\lib\urllib\request.py", line 455, in open
    response = self._open(req, data)
  File "C:\Python34\lib\urllib\request.py", line 473, in _open
    '_open', req)
  File "C:\Python34\lib\urllib\request.py", line 433, in _call_chain
    result = func(*args)
  File "C:\Python34\lib\urllib\request.py", line 1215, in http_open
    return self.do_open(http.client.HTTPConnection, req)
  File "C:\Python34\lib\urllib\request.py", line 1192, in do_open
    raise URLError(err)
urllib.error.URLError: <urlopen error [WinError 10060] A connection attempt failed because the connected party did not properly respond after a period of time, or established connection failed because connected host has failed to respond>
[EXCEPTION] [2015-02-23|14:03:35] URL Error... Timeout?
<urlopen error [WinError 10060] A connection attempt failed because the connected party did not properly respond after a period of time, or established connection failed because connected host has failed to respond>
[EXCEPTION] [2015-02-23|14:03:35] Traceback (most recent call last):
  File "C:\Python34\lib\urllib\request.py", line 1189, in do_open
    h.request(req.get_method(), req.selector, req.data, headers)
  File "C:\Python34\lib\http\client.py", line 1090, in request
    self._send_request(method, url, body, headers)
  File "C:\Python34\lib\http\client.py", line 1128, in _send_request
    self.endheaders(body)
  File "C:\Python34\lib\http\client.py", line 1086, in endheaders
    self._send_output(message_body)
  File "C:\Python34\lib\http\client.py", line 924, in _send_output
    self.send(msg)
  File "C:\Python34\lib\http\client.py", line 859, in send
    self.connect()
  File "C:\Python34\lib\http\client.py", line 836, in connect
    self.timeout, self.source_address)
  File "C:\Python34\lib\socket.py", line 509, in create_connection
    raise err
  File "C:\Python34\lib\socket.py", line 500, in create_connection
    sock.connect(sa)
TimeoutError: [WinError 10060] A connection attempt failed because the connected party did not properly respond after a period of time, or established connection failed because connected host has failed to respond

During handling of the above exception, another exception occurred:

Traceback (most recent call last):
  File "C:\Users\PD\Documents\polly\pythonDongle\remote_monitor.py", line 15, in send_request
    wp = urllib2.urlopen(http_request, timeout=d.web_request_timeout)
  File "C:\Python34\lib\urllib\request.py", line 153, in urlopen
    return opener.open(url, data, timeout)
  File "C:\Python34\lib\urllib\request.py", line 455, in open
    response = self._open(req, data)
  File "C:\Python34\lib\urllib\request.py", line 473, in _open
    '_open', req)
  File "C:\Python34\lib\urllib\request.py", line 433, in _call_chain
    result = func(*args)
  File "C:\Python34\lib\urllib\request.py", line 1215, in http_open
    return self.do_open(http.client.HTTPConnection, req)
  File "C:\Python34\lib\urllib\request.py", line 1192, in do_open
    raise URLError(err)
urllib.error.URLError: <urlopen error [WinError 10060] A connection attempt failed because the connected party did not properly respond after a period of time, or established connection failed because connected host has failed to respond>
[EXCEPTION] [2015-02-23|14:04:47] >>>> Retrying request: http://128.2.211.183/wa/RemoteMonitor/dongleMontiorUpdate.php?update=QUxJVkU7WzIwMTUtMDItMjN8MTQ6MDM6MTBdOzE7MTQ7Q2VsbGNvbSBHTjtSRUFEWTtDT00xNw==
[EXCEPTION] [2015-02-23|14:04:51] >>>> Retrying request: http://128.2.211.183/wa/RemoteMonitor/dongleMontiorUpdate.php?update=TE9HOytDU1EgUmVzcG9uc2U6IEFUK0NTUQ0NCitDU1E6IDE0LDk5DQoNCk9LDQo=
[EXCEPTION] [2015-02-23|18:25:21] An Exception occurred!
''
[EXCEPTION] [2015-02-23|18:25:21] Traceback (most recent call last):
  File "C:\Users\PD\Documents\polly\pythonDongle\remote_monitor.py", line 15, in send_request
    wp = urllib2.urlopen(http_request, timeout=d.web_request_timeout)
  File "C:\Python34\lib\urllib\request.py", line 153, in urlopen
    return opener.open(url, data, timeout)
  File "C:\Python34\lib\urllib\request.py", line 455, in open
    response = self._open(req, data)
  File "C:\Python34\lib\urllib\request.py", line 473, in _open
    '_open', req)
  File "C:\Python34\lib\urllib\request.py", line 433, in _call_chain
    result = func(*args)
  File "C:\Python34\lib\urllib\request.py", line 1215, in http_open
    return self.do_open(http.client.HTTPConnection, req)
  File "C:\Python34\lib\urllib\request.py", line 1194, in do_open
    r = h.getresponse()
  File "C:\Python34\lib\http\client.py", line 1172, in getresponse
    response.begin()
  File "C:\Python34\lib\http\client.py", line 351, in begin
    version, status, reason = self._read_status()
  File "C:\Python34\lib\http\client.py", line 321, in _read_status
    raise BadStatusLine(line)
http.client.BadStatusLine: ''
[EXCEPTION] [2015-02-23|18:25:21] Moving on... Tired of getting SMSs about this...
[EXCEPTION] [2015-02-23|18:25:21] >>>> Retrying request: http://128.2.211.183/wa/RemoteMonitor/dongleMontiorUpdate.php?update=TE9HO1tDT00xN10gWzIwMTUtMDItMjN8MTg6MjU6MjBdIFNlbmRpbmcga2VlcC1hbGl2ZSBtZXNzYWdlIHRvIHNlcnZlci4uLg==
[EXCEPTION] [2015-02-23|18:30:07] An Exception occurred!
''
[EXCEPTION] [2015-02-23|18:30:07] Traceback (most recent call last):
  File "C:\Users\PD\Documents\polly\pythonDongle\remote_monitor.py", line 15, in send_request
    wp = urllib2.urlopen(http_request, timeout=d.web_request_timeout)
  File "C:\Python34\lib\urllib\request.py", line 153, in urlopen
    return opener.open(url, data, timeout)
  File "C:\Python34\lib\urllib\request.py", line 455, in open
    response = self._open(req, data)
  File "C:\Python34\lib\urllib\request.py", line 473, in _open
    '_open', req)
  File "C:\Python34\lib\urllib\request.py", line 433, in _call_chain
    result = func(*args)
  File "C:\Python34\lib\urllib\request.py", line 1215, in http_open
    return self.do_open(http.client.HTTPConnection, req)
  File "C:\Python34\lib\urllib\request.py", line 1194, in do_open
    r = h.getresponse()
  File "C:\Python34\lib\http\client.py", line 1172, in getresponse
    response.begin()
  File "C:\Python34\lib\http\client.py", line 351, in begin
    version, status, reason = self._read_status()
  File "C:\Python34\lib\http\client.py", line 321, in _read_status
    raise BadStatusLine(line)
http.client.BadStatusLine: ''
[EXCEPTION] [2015-02-23|18:30:07] Moving on... Tired of getting SMSs about this...
[EXCEPTION] [2015-02-23|18:30:08] >>>> Retrying request: http://128.2.211.183/wa/RemoteMonitor/dongleMontiorUpdate.php?update=TE9HO0FUK0NOVU0gUmVzcG9uc2U6IEFUK0NOVU0NDQpPSw0K
